INFO 2019-07-01 11:27:27,387 basehttp 124 "GET /image_codes/11 HTTP/1.1" 301 0
INFO 2019-07-01 11:27:29,877 basehttp 124 "GET /image_codes/11 HTTP/1.1" 301 0
ERROR 2019-07-01 11:27:48,414 exception 135 Internal Server Error: /image_codes/11/
Traceback (most recent call last):
  File "/home/python/.virtualenvs/gangquan_12/lib/python3.5/site-packages/redis/connection.py", line 492, in connect
    sock = self._connect()
  File "/home/python/.virtualenvs/gangquan_12/lib/python3.5/site-packages/redis/connection.py", line 550, in _connect
    raise err
  File "/home/python/.virtualenvs/gangquan_12/lib/python3.5/site-packages/redis/connection.py", line 538, in _connect
    sock.connect(socket_address)
ConnectionRefusedError: [Errno 111] Connection refused

During handling of the above exception, another exception occurred:

Traceback (most recent call last):
  File "/home/python/.virtualenvs/gangquan_12/lib/python3.5/site-packages/rest_framework/views.py", line 492, in dispatch
    response = handler(request, *args, **kwargs)
  File "/home/python/Desktop/gangquanwang/gangquan_12/gangquan_12/apps/verifications/views.py", line 22, in get
    redis_conn.setex('img_%s' % image_code_id, constants.IMAGE_CODE_REDIS_EXPIRES , text)
  File "/home/python/.virtualenvs/gangquan_12/lib/python3.5/site-packages/redis/client.py", line 1472, in setex
    return self.execute_command('SETEX', name, time, value)
  File "/home/python/.virtualenvs/gangquan_12/lib/python3.5/site-packages/redis/client.py", line 772, in execute_command
    connection = pool.get_connection(command_name, **options)
  File "/home/python/.virtualenvs/gangquan_12/lib/python3.5/site-packages/redis/connection.py", line 994, in get_connection
    connection.connect()
  File "/home/python/.virtualenvs/gangquan_12/lib/python3.5/site-packages/redis/connection.py", line 497, in connect
    raise ConnectionError(self._error_message(e))
redis.exceptions.ConnectionError: Error 111 connecting to 10.211.55.5:6379. Connection refused.

During handling of the above exception, another exception occurred:

Traceback (most recent call last):
  File "/home/python/.virtualenvs/gangquan_12/lib/python3.5/site-packages/rest_framework/settings.py", line 183, in import_from_string
    module = import_module(module_path)
  File "/home/python/.virtualenvs/gangquan_12/lib/python3.5/importlib/__init__.py", line 126, in import_module
    return _bootstrap._gcd_import(name[level:], package, level)
  File "<frozen importlib._bootstrap>", line 986, in _gcd_import
  File "<frozen importlib._bootstrap>", line 969, in _find_and_load
  File "<frozen importlib._bootstrap>", line 956, in _find_and_load_unlocked
ImportError: No module named 'gangquan_12.utils.exceptions'

During handling of the above exception, another exception occurred:

Traceback (most recent call last):
  File "/home/python/.virtualenvs/gangquan_12/lib/python3.5/site-packages/django/core/handlers/exception.py", line 41, in inner
    response = get_response(request)
  File "/home/python/.virtualenvs/gangquan_12/lib/python3.5/site-packages/django/core/handlers/base.py", line 187, in _get_response
    response = self.process_exception_by_middleware(e, request)
  File "/home/python/.virtualenvs/gangquan_12/lib/python3.5/site-packages/django/core/handlers/base.py", line 185, in _get_response
    response = wrapped_callback(request, *callback_args, **callback_kwargs)
  File "/home/python/.virtualenvs/gangquan_12/lib/python3.5/site-packages/django/views/decorators/csrf.py", line 58, in wrapped_view
    return view_func(*args, **kwargs)
  File "/home/python/.virtualenvs/gangquan_12/lib/python3.5/site-packages/django/views/generic/base.py", line 68, in view
    return self.dispatch(request, *args, **kwargs)
  File "/home/python/.virtualenvs/gangquan_12/lib/python3.5/site-packages/rest_framework/views.py", line 495, in dispatch
    response = self.handle_exception(exc)
  File "/home/python/.virtualenvs/gangquan_12/lib/python3.5/site-packages/rest_framework/views.py", line 449, in handle_exception
    exception_handler = self.get_exception_handler()
  File "/home/python/.virtualenvs/gangquan_12/lib/python3.5/site-packages/rest_framework/views.py", line 300, in get_exception_handler
    return self.settings.EXCEPTION_HANDLER
  File "/home/python/.virtualenvs/gangquan_12/lib/python3.5/site-packages/rest_framework/settings.py", line 227, in __getattr__
    val = perform_import(val, attr)
  File "/home/python/.virtualenvs/gangquan_12/lib/python3.5/site-packages/rest_framework/settings.py", line 170, in perform_import
    return import_from_string(val, setting_name)
  File "/home/python/.virtualenvs/gangquan_12/lib/python3.5/site-packages/rest_framework/settings.py", line 187, in import_from_string
    raise ImportError(msg)
ImportError: Could not import 'gangquan_12.utils.exceptions.exception_handler' for API setting 'EXCEPTION_HANDLER'. ImportError: No module named 'gangquan_12.utils.exceptions'.
ERROR 2019-07-01 11:27:48,611 basehttp 124 "GET /image_codes/11/ HTTP/1.1" 500 158427
ERROR 2019-07-01 11:27:50,890 exception 135 Internal Server Error: /image_codes/11/
Traceback (most recent call last):
  File "/home/python/.virtualenvs/gangquan_12/lib/python3.5/site-packages/redis/connection.py", line 492, in connect
    sock = self._connect()
  File "/home/python/.virtualenvs/gangquan_12/lib/python3.5/site-packages/redis/connection.py", line 550, in _connect
    raise err
  File "/home/python/.virtualenvs/gangquan_12/lib/python3.5/site-packages/redis/connection.py", line 538, in _connect
    sock.connect(socket_address)
ConnectionRefusedError: [Errno 111] Connection refused

During handling of the above exception, another exception occurred:

Traceback (most recent call last):
  File "/home/python/.virtualenvs/gangquan_12/lib/python3.5/site-packages/rest_framework/views.py", line 492, in dispatch
    response = handler(request, *args, **kwargs)
  File "/home/python/Desktop/gangquanwang/gangquan_12/gangquan_12/apps/verifications/views.py", line 22, in get
    redis_conn.setex('img_%s' % image_code_id, constants.IMAGE_CODE_REDIS_EXPIRES , text)
  File "/home/python/.virtualenvs/gangquan_12/lib/python3.5/site-packages/redis/client.py", line 1472, in setex
    return self.execute_command('SETEX', name, time, value)
  File "/home/python/.virtualenvs/gangquan_12/lib/python3.5/site-packages/redis/client.py", line 772, in execute_command
    connection = pool.get_connection(command_name, **options)
  File "/home/python/.virtualenvs/gangquan_12/lib/python3.5/site-packages/redis/connection.py", line 994, in get_connection
    connection.connect()
  File "/home/python/.virtualenvs/gangquan_12/lib/python3.5/site-packages/redis/connection.py", line 497, in connect
    raise ConnectionError(self._error_message(e))
redis.exceptions.ConnectionError: Error 111 connecting to 10.211.55.5:6379. Connection refused.

During handling of the above exception, another exception occurred:

Traceback (most recent call last):
  File "/home/python/.virtualenvs/gangquan_12/lib/python3.5/site-packages/rest_framework/settings.py", line 183, in import_from_string
    module = import_module(module_path)
  File "/home/python/.virtualenvs/gangquan_12/lib/python3.5/importlib/__init__.py", line 126, in import_module
    return _bootstrap._gcd_import(name[level:], package, level)
  File "<frozen importlib._bootstrap>", line 986, in _gcd_import
  File "<frozen importlib._bootstrap>", line 969, in _find_and_load
  File "<frozen importlib._bootstrap>", line 956, in _find_and_load_unlocked
ImportError: No module named 'gangquan_12.utils.exceptions'

During handling of the above exception, another exception occurred:

Traceback (most recent call last):
  File "/home/python/.virtualenvs/gangquan_12/lib/python3.5/site-packages/django/core/handlers/exception.py", line 41, in inner
    response = get_response(request)
  File "/home/python/.virtualenvs/gangquan_12/lib/python3.5/site-packages/django/core/handlers/base.py", line 187, in _get_response
    response = self.process_exception_by_middleware(e, request)
  File "/home/python/.virtualenvs/gangquan_12/lib/python3.5/site-packages/django/core/handlers/base.py", line 185, in _get_response
    response = wrapped_callback(request, *callback_args, **callback_kwargs)
  File "/home/python/.virtualenvs/gangquan_12/lib/python3.5/site-packages/django/views/decorators/csrf.py", line 58, in wrapped_view
    return view_func(*args, **kwargs)
  File "/home/python/.virtualenvs/gangquan_12/lib/python3.5/site-packages/django/views/generic/base.py", line 68, in view
    return self.dispatch(request, *args, **kwargs)
  File "/home/python/.virtualenvs/gangquan_12/lib/python3.5/site-packages/rest_framework/views.py", line 495, in dispatch
    response = self.handle_exception(exc)
  File "/home/python/.virtualenvs/gangquan_12/lib/python3.5/site-packages/rest_framework/views.py", line 449, in handle_exception
    exception_handler = self.get_exception_handler()
  File "/home/python/.virtualenvs/gangquan_12/lib/python3.5/site-packages/rest_framework/views.py", line 300, in get_exception_handler
    return self.settings.EXCEPTION_HANDLER
  File "/home/python/.virtualenvs/gangquan_12/lib/python3.5/site-packages/rest_framework/settings.py", line 227, in __getattr__
    val = perform_import(val, attr)
  File "/home/python/.virtualenvs/gangquan_12/lib/python3.5/site-packages/rest_framework/settings.py", line 170, in perform_import
    return import_from_string(val, setting_name)
  File "/home/python/.virtualenvs/gangquan_12/lib/python3.5/site-packages/rest_framework/settings.py", line 187, in import_from_string
    raise ImportError(msg)
ImportError: Could not import 'gangquan_12.utils.exceptions.exception_handler' for API setting 'EXCEPTION_HANDLER'. ImportError: No module named 'gangquan_12.utils.exceptions'.
ERROR 2019-07-01 11:27:50,997 basehttp 124 "GET /image_codes/11/ HTTP/1.1" 500 158557
WARNING 2019-07-01 11:27:51,326 base 152 Not Found: /favicon.ico
WARNING 2019-07-01 11:27:51,326 basehttp 124 "GET /favicon.ico HTTP/1.1" 404 2161
INFO 2019-07-01 11:29:04,081 basehttp 124 "GET /image_codes/11/ HTTP/1.1" 200 3191
INFO 2019-07-01 11:29:13,403 basehttp 124 "GET /image_codes/12/ HTTP/1.1" 200 3359
INFO 2019-07-01 11:29:21,412 basehttp 124 "GET /image_codes/13/ HTTP/1.1" 200 3323
INFO 2019-07-01 11:30:24,959 basehttp 124 "GET /image_codes/13/ HTTP/1.1" 200 2943
INFO 2019-07-01 11:30:29,416 basehttp 124 "GET /image_codes/13/ HTTP/1.1" 200 3426
WARNING 2019-07-01 11:34:41,782 base 152 Not Found: /
WARNING 2019-07-01 11:34:41,783 basehttp 124 "GET / HTTP/1.1" 404 2110
INFO 2019-07-01 11:34:53,578 basehttp 124 "GET /image_codes/11/ HTTP/1.1" 200 3029
INFO 2019-07-01 12:39:46,555 basehttp 124 "GET /image_codes/ab9eacc3-9e99-41eb-89d4-c2ebe2a1a8b9/ HTTP/1.1" 200 2847
INFO 2019-07-01 12:39:55,117 basehttp 124 "GET /image_codes/3cd17993-0807-444b-a2f2-b0212345fc6c/ HTTP/1.1" 200 2921
INFO 2019-07-01 12:39:55,405 basehttp 124 "GET /image_codes/e946a6b5-cac3-4259-b766-57b26458b6a0/ HTTP/1.1" 200 3110
INFO 2019-07-01 12:39:55,816 basehttp 124 "GET /image_codes/1f96cd37-9fa5-4b58-a2db-19aeacfc2b2d/ HTTP/1.1" 200 3186
INFO 2019-07-01 12:39:56,033 basehttp 124 "GET /image_codes/ec5d74c4-6309-48c3-a429-70d101c67b55/ HTTP/1.1" 200 3219
INFO 2019-07-01 12:39:56,200 basehttp 124 "GET /image_codes/1c1b4fd0-17ef-4949-aad5-85b400d0cb05/ HTTP/1.1" 200 2899
INFO 2019-07-01 12:39:56,381 basehttp 124 "GET /image_codes/b0be4ba3-0c6b-4a14-9ba2-1a610fca47d9/ HTTP/1.1" 200 2652
WARNING 2019-07-01 17:32:32,977 base 152 Not Found: /sms_code/15290980528/
WARNING 2019-07-01 17:32:32,979 basehttp 124 "GET /sms_code/15290980528/?text=12345&bbb=3333 HTTP/1.1" 404 2407
WARNING 2019-07-01 18:01:28,061 base 152 Not Found: /sms_code/15290980528/
WARNING 2019-07-01 18:01:28,061 basehttp 124 "GET /sms_code/15290980528/?text=12345&bbb=3333 HTTP/1.1" 404 2407
WARNING 2019-07-01 18:03:54,047 base 152 Not Found: /sms_code/15290980528/
WARNING 2019-07-01 18:03:54,047 basehttp 124 "GET /sms_code/15290980528/?text=12345&bbb=3333 HTTP/1.1" 404 2401
WARNING 2019-07-01 18:05:13,531 base 152 Not Found: /sms_code/15290980528/
WARNING 2019-07-01 18:05:13,532 basehttp 124 "GET /sms_code/15290980528/?text=12345&bbb=3333 HTTP/1.1" 404 2401
WARNING 2019-07-01 18:06:01,975 base 152 Not Found: /sms_code/15290980528/
WARNING 2019-07-01 18:06:01,976 basehttp 124 "GET /sms_code/15290980528/?text=12345&bbb=3333 HTTP/1.1" 404 2400
ERROR 2019-07-01 18:08:06,972 exception 135 Internal Server Error: /sms_code/15290980528/
Traceback (most recent call last):
  File "/home/python/.virtualenvs/gangquan_12/lib/python3.5/site-packages/rest_framework/views.py", line 492, in dispatch
    response = handler(request, *args, **kwargs)
  File "/home/python/Desktop/gangquanwang/gangquan_12/gangquan_12/apps/verifications/views.py", line 47, in get
    serialzier.is_valid(raise_exception=True)
  File "/home/python/.virtualenvs/gangquan_12/lib/python3.5/site-packages/rest_framework/serializers.py", line 244, in is_valid
    raise ValidationError(self.errors)
rest_framework.exceptions.ValidationError: {'image_code_id': [ErrorDetail(string='该字段是必填项。', code='required')], 'text': [ErrorDetail(string='请确保这个字段不能超过 4 个字符。', code='max_length')]}

During handling of the above exception, another exception occurred:

Traceback (most recent call last):
  File "/home/python/.virtualenvs/gangquan_12/lib/python3.5/site-packages/rest_framework/settings.py", line 183, in import_from_string
    module = import_module(module_path)
  File "/home/python/.virtualenvs/gangquan_12/lib/python3.5/importlib/__init__.py", line 126, in import_module
    return _bootstrap._gcd_import(name[level:], package, level)
  File "<frozen importlib._bootstrap>", line 986, in _gcd_import
  File "<frozen importlib._bootstrap>", line 969, in _find_and_load
  File "<frozen importlib._bootstrap>", line 956, in _find_and_load_unlocked
ImportError: No module named 'gangquan_12.utils.exceptions'

During handling of the above exception, another exception occurred:

Traceback (most recent call last):
  File "/home/python/.virtualenvs/gangquan_12/lib/python3.5/site-packages/django/core/handlers/exception.py", line 41, in inner
    response = get_response(request)
  File "/home/python/.virtualenvs/gangquan_12/lib/python3.5/site-packages/django/core/handlers/base.py", line 187, in _get_response
    response = self.process_exception_by_middleware(e, request)
  File "/home/python/.virtualenvs/gangquan_12/lib/python3.5/site-packages/django/core/handlers/base.py", line 185, in _get_response
    response = wrapped_callback(request, *callback_args, **callback_kwargs)
  File "/home/python/.virtualenvs/gangquan_12/lib/python3.5/site-packages/django/views/decorators/csrf.py", line 58, in wrapped_view
    return view_func(*args, **kwargs)
  File "/home/python/.virtualenvs/gangquan_12/lib/python3.5/site-packages/django/views/generic/base.py", line 68, in view
    return self.dispatch(request, *args, **kwargs)
  File "/home/python/.virtualenvs/gangquan_12/lib/python3.5/site-packages/rest_framework/views.py", line 495, in dispatch
    response = self.handle_exception(exc)
  File "/home/python/.virtualenvs/gangquan_12/lib/python3.5/site-packages/rest_framework/views.py", line 449, in handle_exception
    exception_handler = self.get_exception_handler()
  File "/home/python/.virtualenvs/gangquan_12/lib/python3.5/site-packages/rest_framework/views.py", line 300, in get_exception_handler
    return self.settings.EXCEPTION_HANDLER
  File "/home/python/.virtualenvs/gangquan_12/lib/python3.5/site-packages/rest_framework/settings.py", line 227, in __getattr__
    val = perform_import(val, attr)
  File "/home/python/.virtualenvs/gangquan_12/lib/python3.5/site-packages/rest_framework/settings.py", line 170, in perform_import
    return import_from_string(val, setting_name)
  File "/home/python/.virtualenvs/gangquan_12/lib/python3.5/site-packages/rest_framework/settings.py", line 187, in import_from_string
    raise ImportError(msg)
ImportError: Could not import 'gangquan_12.utils.exceptions.exception_handler' for API setting 'EXCEPTION_HANDLER'. ImportError: No module named 'gangquan_12.utils.exceptions'.
ERROR 2019-07-01 18:08:07,180 basehttp 124 "GET /sms_code/15290980528/?text=12345&bbb=3333 HTTP/1.1" 500 126651
ERROR 2019-07-01 18:19:48,194 exception 135 Internal Server Error: /sms_code/15290980528/
Traceback (most recent call last):
  File "/home/python/.virtualenvs/gangquan_12/lib/python3.5/site-packages/rest_framework/views.py", line 492, in dispatch
    response = handler(request, *args, **kwargs)
  File "/home/python/Desktop/gangquanwang/gangquan_12/gangquan_12/apps/verifications/views.py", line 47, in get
    serialzier.is_valid(raise_exception=True)
  File "/home/python/.virtualenvs/gangquan_12/lib/python3.5/site-packages/rest_framework/serializers.py", line 244, in is_valid
    raise ValidationError(self.errors)
rest_framework.exceptions.ValidationError: {'image_code_id': [ErrorDetail(string='该字段是必填项。', code='required')], 'text': [ErrorDetail(string='请确保这个字段不能超过 4 个字符。', code='max_length')]}

During handling of the above exception, another exception occurred:

Traceback (most recent call last):
  File "/home/python/.virtualenvs/gangquan_12/lib/python3.5/site-packages/rest_framework/settings.py", line 183, in import_from_string
    module = import_module(module_path)
  File "/home/python/.virtualenvs/gangquan_12/lib/python3.5/importlib/__init__.py", line 126, in import_module
    return _bootstrap._gcd_import(name[level:], package, level)
  File "<frozen importlib._bootstrap>", line 986, in _gcd_import
  File "<frozen importlib._bootstrap>", line 969, in _find_and_load
  File "<frozen importlib._bootstrap>", line 956, in _find_and_load_unlocked
ImportError: No module named 'gangquan_12.utils.exceptions'

During handling of the above exception, another exception occurred:

Traceback (most recent call last):
  File "/home/python/.virtualenvs/gangquan_12/lib/python3.5/site-packages/django/core/handlers/exception.py", line 41, in inner
    response = get_response(request)
  File "/home/python/.virtualenvs/gangquan_12/lib/python3.5/site-packages/django/core/handlers/base.py", line 187, in _get_response
    response = self.process_exception_by_middleware(e, request)
  File "/home/python/.virtualenvs/gangquan_12/lib/python3.5/site-packages/django/core/handlers/base.py", line 185, in _get_response
    response = wrapped_callback(request, *callback_args, **callback_kwargs)
  File "/home/python/.virtualenvs/gangquan_12/lib/python3.5/site-packages/django/views/decorators/csrf.py", line 58, in wrapped_view
    return view_func(*args, **kwargs)
  File "/home/python/.virtualenvs/gangquan_12/lib/python3.5/site-packages/django/views/generic/base.py", line 68, in view
    return self.dispatch(request, *args, **kwargs)
  File "/home/python/.virtualenvs/gangquan_12/lib/python3.5/site-packages/rest_framework/views.py", line 495, in dispatch
    response = self.handle_exception(exc)
  File "/home/python/.virtualenvs/gangquan_12/lib/python3.5/site-packages/rest_framework/views.py", line 449, in handle_exception
    exception_handler = self.get_exception_handler()
  File "/home/python/.virtualenvs/gangquan_12/lib/python3.5/site-packages/rest_framework/views.py", line 300, in get_exception_handler
    return self.settings.EXCEPTION_HANDLER
  File "/home/python/.virtualenvs/gangquan_12/lib/python3.5/site-packages/rest_framework/settings.py", line 227, in __getattr__
    val = perform_import(val, attr)
  File "/home/python/.virtualenvs/gangquan_12/lib/python3.5/site-packages/rest_framework/settings.py", line 170, in perform_import
    return import_from_string(val, setting_name)
  File "/home/python/.virtualenvs/gangquan_12/lib/python3.5/site-packages/rest_framework/settings.py", line 187, in import_from_string
    raise ImportError(msg)
ImportError: Could not import 'gangquan_12.utils.exceptions.exception_handler' for API setting 'EXCEPTION_HANDLER'. ImportError: No module named 'gangquan_12.utils.exceptions'.
ERROR 2019-07-01 18:19:48,278 basehttp 124 "GET /sms_code/15290980528/?text=12345&bbb=3333 HTTP/1.1" 500 126651
ERROR 2019-07-01 18:21:40,703 exception 135 Internal Server Error: /sms_code/15290980528/
Traceback (most recent call last):
  File "/home/python/.virtualenvs/gangquan_12/lib/python3.5/site-packages/rest_framework/views.py", line 492, in dispatch
    response = handler(request, *args, **kwargs)
  File "/home/python/Desktop/gangquanwang/gangquan_12/gangquan_12/apps/verifications/views.py", line 47, in get
    serialzier.is_valid(raise_exception=True)
  File "/home/python/.virtualenvs/gangquan_12/lib/python3.5/site-packages/rest_framework/serializers.py", line 244, in is_valid
    raise ValidationError(self.errors)
rest_framework.exceptions.ValidationError: {'image_code_id': [ErrorDetail(string='该字段是必填项。', code='required')], 'text': [ErrorDetail(string='请确保这个字段不能超过 4 个字符。', code='max_length')]}

During handling of the above exception, another exception occurred:

Traceback (most recent call last):
  File "/home/python/.virtualenvs/gangquan_12/lib/python3.5/site-packages/rest_framework/settings.py", line 183, in import_from_string
    module = import_module(module_path)
  File "/home/python/.virtualenvs/gangquan_12/lib/python3.5/importlib/__init__.py", line 126, in import_module
    return _bootstrap._gcd_import(name[level:], package, level)
  File "<frozen importlib._bootstrap>", line 986, in _gcd_import
  File "<frozen importlib._bootstrap>", line 969, in _find_and_load
  File "<frozen importlib._bootstrap>", line 956, in _find_and_load_unlocked
ImportError: No module named 'gangquan_12.utils.exceptions'

During handling of the above exception, another exception occurred:

Traceback (most recent call last):
  File "/home/python/.virtualenvs/gangquan_12/lib/python3.5/site-packages/django/core/handlers/exception.py", line 41, in inner
    response = get_response(request)
  File "/home/python/.virtualenvs/gangquan_12/lib/python3.5/site-packages/django/core/handlers/base.py", line 187, in _get_response
    response = self.process_exception_by_middleware(e, request)
  File "/home/python/.virtualenvs/gangquan_12/lib/python3.5/site-packages/django/core/handlers/base.py", line 185, in _get_response
    response = wrapped_callback(request, *callback_args, **callback_kwargs)
  File "/home/python/.virtualenvs/gangquan_12/lib/python3.5/site-packages/django/views/decorators/csrf.py", line 58, in wrapped_view
    return view_func(*args, **kwargs)
  File "/home/python/.virtualenvs/gangquan_12/lib/python3.5/site-packages/django/views/generic/base.py", line 68, in view
    return self.dispatch(request, *args, **kwargs)
  File "/home/python/.virtualenvs/gangquan_12/lib/python3.5/site-packages/rest_framework/views.py", line 495, in dispatch
    response = self.handle_exception(exc)
  File "/home/python/.virtualenvs/gangquan_12/lib/python3.5/site-packages/rest_framework/views.py", line 449, in handle_exception
    exception_handler = self.get_exception_handler()
  File "/home/python/.virtualenvs/gangquan_12/lib/python3.5/site-packages/rest_framework/views.py", line 300, in get_exception_handler
    return self.settings.EXCEPTION_HANDLER
  File "/home/python/.virtualenvs/gangquan_12/lib/python3.5/site-packages/rest_framework/settings.py", line 227, in __getattr__
    val = perform_import(val, attr)
  File "/home/python/.virtualenvs/gangquan_12/lib/python3.5/site-packages/rest_framework/settings.py", line 170, in perform_import
    return import_from_string(val, setting_name)
  File "/home/python/.virtualenvs/gangquan_12/lib/python3.5/site-packages/rest_framework/settings.py", line 187, in import_from_string
    raise ImportError(msg)
ImportError: Could not import 'gangquan_12.utils.exceptions.exception_handler' for API setting 'EXCEPTION_HANDLER'. ImportError: No module named 'gangquan_12.utils.exceptions'.
ERROR 2019-07-01 18:21:41,181 basehttp 124 "GET /sms_code/15290980528/?text=12345&bbb=3333 HTTP/1.1" 500 128099
INFO 2019-07-01 18:24:29,829 basehttp 124 "GET /image_codes/aa10d41a-e1a4-4809-86ac-3acd1fc5cc99/ HTTP/1.1" 200 3101
INFO 2019-07-01 18:35:58,234 basehttp 124 "GET /image_codes/a15ccdde-f8ed-4a27-9290-67d47507877b/ HTTP/1.1" 200 3230
INFO 2019-07-01 18:36:17,088 basehttp 124 "GET /image_codes/8b6d4652-3057-4837-a20c-87da5f30cb41/ HTTP/1.1" 200 3625
WARNING 2019-07-01 18:36:32,929 base 152 Not Found: /sms_codes/15290980528/
WARNING 2019-07-01 18:36:32,930 basehttp 124 "GET /sms_codes/15290980528/?text=wwww&image_code_id=8b6d4652-3057-4837-a20c-87da5f30cb41 HTTP/1.1" 404 2452
WARNING 2019-07-01 18:36:53,493 base 152 Not Found: /sms_codes/15290980528/
WARNING 2019-07-01 18:36:53,494 basehttp 124 "GET /sms_codes/15290980528/?text=wwww&image_code_id=8b6d4652-3057-4837-a20c-87da5f30cb41 HTTP/1.1" 404 2452
WARNING 2019-07-01 18:36:53,599 base 152 Not Found: /favicon.ico
WARNING 2019-07-01 18:36:53,600 basehttp 124 "GET /favicon.ico HTTP/1.1" 404 2354
WARNING 2019-07-01 18:37:37,647 base 152 Not Found: /sms_codes/15290980528/
WARNING 2019-07-01 18:37:37,649 basehttp 124 "GET /sms_codes/15290980528/?text=wwww&image_code_id=8b6d4652-3057-4837-a20c-87da5f30cb41 HTTP/1.1" 404 2452
WARNING 2019-07-01 18:38:04,252 base 152 Not Found: /sms_codes/15290980528/
WARNING 2019-07-01 18:38:04,253 basehttp 124 "GET /sms_codes/15290980528/?text=wwww&image_code_id=8b6d4652-3057-4837-a20c-87da5f30cb41 HTTP/1.1" 404 2452
INFO 2019-07-01 18:38:45,656 basehttp 124 "GET /image_codes/a1f41168-e6c2-4aca-929f-a124ee3a39ff/ HTTP/1.1" 200 3500
WARNING 2019-07-01 18:38:56,588 base 152 Not Found: /sms_codes/15290980528/
WARNING 2019-07-01 18:38:56,589 basehttp 124 "GET /sms_codes/15290980528/?text=qwet&image_code_id=a1f41168-e6c2-4aca-929f-a124ee3a39ff HTTP/1.1" 404 2452
WARNING 2019-07-01 18:39:10,626 base 152 Not Found: /sms_codes/15290980528/
WARNING 2019-07-01 18:39:10,627 basehttp 124 "GET /sms_codes/15290980528/?text=qwet&image_code_id=a1f41168-e6c2-4aca-929f-a124ee3a39ff HTTP/1.1" 404 2452
WARNING 2019-07-01 18:39:50,407 base 152 Not Found: /sms_codes/15290980528/
WARNING 2019-07-01 18:39:50,408 basehttp 124 "GET /sms_codes/15290980528/?text=qwet&image_code_id=a1f41168-e6c2-4aca-929f-a124ee3a39ff HTTP/1.1" 404 2452
INFO 2019-07-01 18:40:13,209 basehttp 124 "GET /image_codes/a11e7b0f-1bb3-4639-af65-d8ce15ffcc8c/ HTTP/1.1" 200 2918
ERROR 2019-07-01 18:40:26,765 exception 135 Internal Server Error: /sms_codes/15290980528/
Traceback (most recent call last):
  File "/home/python/.virtualenvs/gangquan_12/lib/python3.5/site-packages/rest_framework/views.py", line 492, in dispatch
    response = handler(request, *args, **kwargs)
  File "/home/python/Desktop/gangquanwang/gangquan_12/gangquan_12/apps/verifications/views.py", line 47, in get
    serialzier.is_valid(raise_exception=True)
  File "/home/python/.virtualenvs/gangquan_12/lib/python3.5/site-packages/rest_framework/serializers.py", line 244, in is_valid
    raise ValidationError(self.errors)
rest_framework.exceptions.ValidationError: {'non_field_errors': [ErrorDetail(string='验证码输入不正确', code='invalid')]}

During handling of the above exception, another exception occurred:

Traceback (most recent call last):
  File "/home/python/.virtualenvs/gangquan_12/lib/python3.5/site-packages/rest_framework/settings.py", line 183, in import_from_string
    module = import_module(module_path)
  File "/home/python/.virtualenvs/gangquan_12/lib/python3.5/importlib/__init__.py", line 126, in import_module
    return _bootstrap._gcd_import(name[level:], package, level)
  File "<frozen importlib._bootstrap>", line 986, in _gcd_import
  File "<frozen importlib._bootstrap>", line 969, in _find_and_load
  File "<frozen importlib._bootstrap>", line 956, in _find_and_load_unlocked
ImportError: No module named 'gangquan_12.utils.exceptions'

During handling of the above exception, another exception occurred:

Traceback (most recent call last):
  File "/home/python/.virtualenvs/gangquan_12/lib/python3.5/site-packages/django/core/handlers/exception.py", line 41, in inner
    response = get_response(request)
  File "/home/python/.virtualenvs/gangquan_12/lib/python3.5/site-packages/django/core/handlers/base.py", line 187, in _get_response
    response = self.process_exception_by_middleware(e, request)
  File "/home/python/.virtualenvs/gangquan_12/lib/python3.5/site-packages/django/core/handlers/base.py", line 185, in _get_response
    response = wrapped_callback(request, *callback_args, **callback_kwargs)
  File "/home/python/.virtualenvs/gangquan_12/lib/python3.5/site-packages/django/views/decorators/csrf.py", line 58, in wrapped_view
    return view_func(*args, **kwargs)
  File "/home/python/.virtualenvs/gangquan_12/lib/python3.5/site-packages/django/views/generic/base.py", line 68, in view
    return self.dispatch(request, *args, **kwargs)
  File "/home/python/.virtualenvs/gangquan_12/lib/python3.5/site-packages/rest_framework/views.py", line 495, in dispatch
    response = self.handle_exception(exc)
  File "/home/python/.virtualenvs/gangquan_12/lib/python3.5/site-packages/rest_framework/views.py", line 449, in handle_exception
    exception_handler = self.get_exception_handler()
  File "/home/python/.virtualenvs/gangquan_12/lib/python3.5/site-packages/rest_framework/views.py", line 300, in get_exception_handler
    return self.settings.EXCEPTION_HANDLER
  File "/home/python/.virtualenvs/gangquan_12/lib/python3.5/site-packages/rest_framework/settings.py", line 227, in __getattr__
    val = perform_import(val, attr)
  File "/home/python/.virtualenvs/gangquan_12/lib/python3.5/site-packages/rest_framework/settings.py", line 170, in perform_import
    return import_from_string(val, setting_name)
  File "/home/python/.virtualenvs/gangquan_12/lib/python3.5/site-packages/rest_framework/settings.py", line 187, in import_from_string
    raise ImportError(msg)
ImportError: Could not import 'gangquan_12.utils.exceptions.exception_handler' for API setting 'EXCEPTION_HANDLER'. ImportError: No module named 'gangquan_12.utils.exceptions'.
ERROR 2019-07-01 18:40:26,849 basehttp 124 "GET /sms_codes/15290980528/?text=pud8&image_code_id=a11e7b0f-1bb3-4639-af65-d8ce15ffcc8c HTTP/1.1" 500 126629
INFO 2019-07-01 18:41:27,914 basehttp 124 "GET /image_codes/5539cb69-90de-4435-8a5b-d80b495e9f79/ HTTP/1.1" 200 3091
INFO 2019-07-01 18:41:34,861 basehttp 124 "GET /image_codes/ee86307d-93f0-420b-8568-717eb9150fa5/ HTTP/1.1" 200 2994
WARNING 2019-07-01 18:42:00,830 views 77 发送短信验证码(失败) mobile:15290980528
ERROR 2019-07-01 18:42:00,831 basehttp 124 "GET /sms_codes/15290980528/?text=zxla&image_code_id=ee86307d-93f0-420b-8568-717eb9150fa5 HTTP/1.1" 507 32
INFO 2019-07-01 18:42:55,948 basehttp 124 "GET /image_codes/ea53ff01-e727-4902-abca-0abd2f8c6455/ HTTP/1.1" 200 3103
WARNING 2019-07-01 18:43:32,495 base 152 Not Found: /
WARNING 2019-07-01 18:43:32,496 basehttp 124 "GET / HTTP/1.1" 404 2298
WARNING 2019-07-01 18:43:32,575 base 152 Not Found: /favicon.ico
WARNING 2019-07-01 18:43:32,575 basehttp 124 "GET /favicon.ico HTTP/1.1" 404 2349
WARNING 2019-07-01 18:44:21,853 base 152 Not Found: /sms_codes/15290980528/text=XB97&image_code_id=ea53ff01-e727-4902-abca-0abd2f8c6455
WARNING 2019-07-01 18:44:21,854 basehttp 124 "GET /sms_codes/15290980528/text=XB97&image_code_id=ea53ff01-e727-4902-abca-0abd2f8c6455 HTTP/1.1" 404 2578
WARNING 2019-07-01 18:45:48,603 views 77 发送短信验证码(失败) mobile:15290980528
ERROR 2019-07-01 18:45:48,915 basehttp 124 "GET /sms_codes/15290980528/?text=XB97&image_code_id=ea53ff01-e727-4902-abca-0abd2f8c6455 HTTP/1.1" 507 5711
INFO 2019-07-01 18:45:48,955 basehttp 124 "GET /static/rest_framework/css/bootstrap-tweaks.css HTTP/1.1" 200 3385
INFO 2019-07-01 18:45:48,958 basehttp 124 "GET /static/rest_framework/css/default.css HTTP/1.1" 200 1131
INFO 2019-07-01 18:45:48,960 basehttp 124 "GET /static/rest_framework/css/prettify.css HTTP/1.1" 200 817
INFO 2019-07-01 18:45:48,967 basehttp 124 "GET /static/rest_framework/js/bootstrap.min.js HTTP/1.1" 200 37608
INFO 2019-07-01 18:45:48,970 basehttp 124 "GET /static/rest_framework/js/ajax-form.js HTTP/1.1" 200 3597
INFO 2019-07-01 18:45:48,973 basehttp 124 "GET /static/rest_framework/js/prettify-min.js HTTP/1.1" 200 13632
INFO 2019-07-01 18:45:48,974 basehttp 124 "GET /static/rest_framework/js/jquery-3.3.1.min.js HTTP/1.1" 200 86927
INFO 2019-07-01 18:45:48,979 basehttp 124 "GET /static/rest_framework/js/csrf.js HTTP/1.1" 200 1719
INFO 2019-07-01 18:45:48,998 basehttp 124 "GET /static/rest_framework/js/default.js HTTP/1.1" 200 1268
INFO 2019-07-01 18:45:49,000 basehttp 124 "GET /static/rest_framework/css/bootstrap.min.css HTTP/1.1" 200 121457
INFO 2019-07-01 18:45:49,250 basehttp 124 "GET /static/rest_framework/img/grid.png HTTP/1.1" 200 1458
INFO 2019-07-01 18:55:17,743 basehttp 124 "GET /image_codes/f41ea84a-0f94-46c4-a5fe-17f822c13659/ HTTP/1.1" 200 3194
WARNING 2019-07-01 18:57:05,102 views 77 发送短信验证码(失败) mobile:15290980528
ERROR 2019-07-01 18:57:05,126 basehttp 124 "GET /sms_codes/15290980528/?text=PW9L&image_code_id=f41ea84a-0f94-46c4-a5fe-17f822c13659 HTTP/1.1" 507 5711
INFO 2019-07-01 19:02:08,796 basehttp 124 "GET /image_codes/475596d3-9fcd-4e69-80dd-566e79c034fe/ HTTP/1.1" 200 3605
INFO 2019-07-01 19:02:59,435 views 74 发送短信验证码(正常) mobile:15290980528
INFO 2019-07-01 19:02:59,459 basehttp 124 "GET /sms_codes/15290980528/?text=8JPM&image_code_id=475596d3-9fcd-4e69-80dd-566e79c034fe HTTP/1.1" 200 5693
ERROR 2019-07-01 19:10:08,324 exception 135 Internal Server Error: /sms_codes/15290980528/
Traceback (most recent call last):
  File "/home/python/.virtualenvs/gangquan_12/lib/python3.5/site-packages/rest_framework/views.py", line 492, in dispatch
    response = handler(request, *args, **kwargs)
  File "/home/python/Desktop/gangquanwang/gangquan_12/gangquan_12/apps/verifications/views.py", line 47, in get
    serialzier.is_valid(raise_exception=True)
  File "/home/python/.virtualenvs/gangquan_12/lib/python3.5/site-packages/rest_framework/serializers.py", line 244, in is_valid
    raise ValidationError(self.errors)
rest_framework.exceptions.ValidationError: {'non_field_errors': [ErrorDetail(string='图片验证码无效', code='invalid')]}

During handling of the above exception, another exception occurred:

Traceback (most recent call last):
  File "/home/python/.virtualenvs/gangquan_12/lib/python3.5/site-packages/rest_framework/settings.py", line 183, in import_from_string
    module = import_module(module_path)
  File "/home/python/.virtualenvs/gangquan_12/lib/python3.5/importlib/__init__.py", line 126, in import_module
    return _bootstrap._gcd_import(name[level:], package, level)
  File "<frozen importlib._bootstrap>", line 986, in _gcd_import
  File "<frozen importlib._bootstrap>", line 969, in _find_and_load
  File "<frozen importlib._bootstrap>", line 956, in _find_and_load_unlocked
ImportError: No module named 'gangquan_12.utils.exceptions'

During handling of the above exception, another exception occurred:

Traceback (most recent call last):
  File "/home/python/.virtualenvs/gangquan_12/lib/python3.5/site-packages/django/core/handlers/exception.py", line 41, in inner
    response = get_response(request)
  File "/home/python/.virtualenvs/gangquan_12/lib/python3.5/site-packages/django/core/handlers/base.py", line 187, in _get_response
    response = self.process_exception_by_middleware(e, request)
  File "/home/python/.virtualenvs/gangquan_12/lib/python3.5/site-packages/django/core/handlers/base.py", line 185, in _get_response
    response = wrapped_callback(request, *callback_args, **callback_kwargs)
  File "/home/python/.virtualenvs/gangquan_12/lib/python3.5/site-packages/django/views/decorators/csrf.py", line 58, in wrapped_view
    return view_func(*args, **kwargs)
  File "/home/python/.virtualenvs/gangquan_12/lib/python3.5/site-packages/django/views/generic/base.py", line 68, in view
    return self.dispatch(request, *args, **kwargs)
  File "/home/python/.virtualenvs/gangquan_12/lib/python3.5/site-packages/rest_framework/views.py", line 495, in dispatch
    response = self.handle_exception(exc)
  File "/home/python/.virtualenvs/gangquan_12/lib/python3.5/site-packages/rest_framework/views.py", line 449, in handle_exception
    exception_handler = self.get_exception_handler()
  File "/home/python/.virtualenvs/gangquan_12/lib/python3.5/site-packages/rest_framework/views.py", line 300, in get_exception_handler
    return self.settings.EXCEPTION_HANDLER
  File "/home/python/.virtualenvs/gangquan_12/lib/python3.5/site-packages/rest_framework/settings.py", line 227, in __getattr__
    val = perform_import(val, attr)
  File "/home/python/.virtualenvs/gangquan_12/lib/python3.5/site-packages/rest_framework/settings.py", line 170, in perform_import
    return import_from_string(val, setting_name)
  File "/home/python/.virtualenvs/gangquan_12/lib/python3.5/site-packages/rest_framework/settings.py", line 187, in import_from_string
    raise ImportError(msg)
ImportError: Could not import 'gangquan_12.utils.exceptions.exception_handler' for API setting 'EXCEPTION_HANDLER'. ImportError: No module named 'gangquan_12.utils.exceptions'.
ERROR 2019-07-01 19:10:08,591 basehttp 124 "GET /sms_codes/15290980528/?text=8jpm&image_code_id=475596d3-9fcd-4e69-80dd-566e79c034fe HTTP/1.1" 500 126620
INFO 2019-07-01 19:16:16,937 basehttp 124 "GET /image_codes/45e9fad2-7ca0-4363-875e-0f39804b8dc4/ HTTP/1.1" 200 3326
ERROR 2019-07-01 19:16:27,368 exception 135 Internal Server Error: /sms_codes/15290980528/
Traceback (most recent call last):
  File "/home/python/.virtualenvs/gangquan_12/lib/python3.5/site-packages/rest_framework/views.py", line 492, in dispatch
    response = handler(request, *args, **kwargs)
  File "/home/python/Desktop/gangquanwang/gangquan_12/gangquan_12/apps/verifications/views.py", line 47, in get
    serialzier.is_valid(raise_exception=True)
  File "/home/python/.virtualenvs/gangquan_12/lib/python3.5/site-packages/rest_framework/serializers.py", line 244, in is_valid
    raise ValidationError(self.errors)
rest_framework.exceptions.ValidationError: {'non_field_errors': [ErrorDetail(string='验证码输入不正确', code='invalid')]}

During handling of the above exception, another exception occurred:

Traceback (most recent call last):
  File "/home/python/.virtualenvs/gangquan_12/lib/python3.5/site-packages/rest_framework/settings.py", line 183, in import_from_string
    module = import_module(module_path)
  File "/home/python/.virtualenvs/gangquan_12/lib/python3.5/importlib/__init__.py", line 126, in import_module
    return _bootstrap._gcd_import(name[level:], package, level)
  File "<frozen importlib._bootstrap>", line 986, in _gcd_import
  File "<frozen importlib._bootstrap>", line 969, in _find_and_load
  File "<frozen importlib._bootstrap>", line 956, in _find_and_load_unlocked
ImportError: No module named 'gangquan_12.utils.exceptions'

During handling of the above exception, another exception occurred:

Traceback (most recent call last):
  File "/home/python/.virtualenvs/gangquan_12/lib/python3.5/site-packages/django/core/handlers/exception.py", line 41, in inner
    response = get_response(request)
  File "/home/python/.virtualenvs/gangquan_12/lib/python3.5/site-packages/django/core/handlers/base.py", line 187, in _get_response
    response = self.process_exception_by_middleware(e, request)
  File "/home/python/.virtualenvs/gangquan_12/lib/python3.5/site-packages/django/core/handlers/base.py", line 185, in _get_response
    response = wrapped_callback(request, *callback_args, **callback_kwargs)
  File "/home/python/.virtualenvs/gangquan_12/lib/python3.5/site-packages/django/views/decorators/csrf.py", line 58, in wrapped_view
    return view_func(*args, **kwargs)
  File "/home/python/.virtualenvs/gangquan_12/lib/python3.5/site-packages/django/views/generic/base.py", line 68, in view
    return self.dispatch(request, *args, **kwargs)
  File "/home/python/.virtualenvs/gangquan_12/lib/python3.5/site-packages/rest_framework/views.py", line 495, in dispatch
    response = self.handle_exception(exc)
  File "/home/python/.virtualenvs/gangquan_12/lib/python3.5/site-packages/rest_framework/views.py", line 449, in handle_exception
    exception_handler = self.get_exception_handler()
  File "/home/python/.virtualenvs/gangquan_12/lib/python3.5/site-packages/rest_framework/views.py", line 300, in get_exception_handler
    return self.settings.EXCEPTION_HANDLER
  File "/home/python/.virtualenvs/gangquan_12/lib/python3.5/site-packages/rest_framework/settings.py", line 227, in __getattr__
    val = perform_import(val, attr)
  File "/home/python/.virtualenvs/gangquan_12/lib/python3.5/site-packages/rest_framework/settings.py", line 170, in perform_import
    return import_from_string(val, setting_name)
  File "/home/python/.virtualenvs/gangquan_12/lib/python3.5/site-packages/rest_framework/settings.py", line 187, in import_from_string
    raise ImportError(msg)
ImportError: Could not import 'gangquan_12.utils.exceptions.exception_handler' for API setting 'EXCEPTION_HANDLER'. ImportError: No module named 'gangquan_12.utils.exceptions'.
ERROR 2019-07-01 19:16:27,448 basehttp 124 "GET /sms_codes/15290980528/?text=1234&image_code_id=45e9fad2-7ca0-4363-875e-0f39804b8dc4 HTTP/1.1" 500 126629
INFO 2019-07-01 19:16:59,798 basehttp 124 "GET /image_codes/e7278cc0-40be-41f0-8020-0ec959674518/ HTTP/1.1" 200 2968
INFO 2019-07-01 19:17:35,313 basehttp 124 "GET /image_codes/f2b231c5-22f8-4ed6-a273-2e531df013dd/ HTTP/1.1" 200 2924
INFO 2019-07-01 19:17:50,326 views 74 发送短信验证码(正常) mobile:15290980528
INFO 2019-07-01 19:17:50,326 basehttp 124 "GET /sms_codes/15290980528/?text=m5r3&image_code_id=f2b231c5-22f8-4ed6-a273-2e531df013dd HTTP/1.1" 200 32
INFO 2019-07-01 19:18:30,661 basehttp 124 "GET /image_codes/83f3b58c-dc44-4713-99b5-acce60e4b904/ HTTP/1.1" 200 3150
ERROR 2019-07-01 19:18:41,511 exception 135 Internal Server Error: /sms_codes/15290980528/
Traceback (most recent call last):
  File "/home/python/.virtualenvs/gangquan_12/lib/python3.5/site-packages/rest_framework/views.py", line 492, in dispatch
    response = handler(request, *args, **kwargs)
  File "/home/python/Desktop/gangquanwang/gangquan_12/gangquan_12/apps/verifications/views.py", line 47, in get
    serialzier.is_valid(raise_exception=True)
  File "/home/python/.virtualenvs/gangquan_12/lib/python3.5/site-packages/rest_framework/serializers.py", line 244, in is_valid
    raise ValidationError(self.errors)
rest_framework.exceptions.ValidationError: {'non_field_errors': [ErrorDetail(string='请求过于频繁', code='invalid')]}

During handling of the above exception, another exception occurred:

Traceback (most recent call last):
  File "/home/python/.virtualenvs/gangquan_12/lib/python3.5/site-packages/rest_framework/settings.py", line 183, in import_from_string
    module = import_module(module_path)
  File "/home/python/.virtualenvs/gangquan_12/lib/python3.5/importlib/__init__.py", line 126, in import_module
    return _bootstrap._gcd_import(name[level:], package, level)
  File "<frozen importlib._bootstrap>", line 986, in _gcd_import
  File "<frozen importlib._bootstrap>", line 969, in _find_and_load
  File "<frozen importlib._bootstrap>", line 956, in _find_and_load_unlocked
ImportError: No module named 'gangquan_12.utils.exceptions'

During handling of the above exception, another exception occurred:

Traceback (most recent call last):
  File "/home/python/.virtualenvs/gangquan_12/lib/python3.5/site-packages/django/core/handlers/exception.py", line 41, in inner
    response = get_response(request)
  File "/home/python/.virtualenvs/gangquan_12/lib/python3.5/site-packages/django/core/handlers/base.py", line 187, in _get_response
    response = self.process_exception_by_middleware(e, request)
  File "/home/python/.virtualenvs/gangquan_12/lib/python3.5/site-packages/django/core/handlers/base.py", line 185, in _get_response
    response = wrapped_callback(request, *callback_args, **callback_kwargs)
  File "/home/python/.virtualenvs/gangquan_12/lib/python3.5/site-packages/django/views/decorators/csrf.py", line 58, in wrapped_view
    return view_func(*args, **kwargs)
  File "/home/python/.virtualenvs/gangquan_12/lib/python3.5/site-packages/django/views/generic/base.py", line 68, in view
    return self.dispatch(request, *args, **kwargs)
  File "/home/python/.virtualenvs/gangquan_12/lib/python3.5/site-packages/rest_framework/views.py", line 495, in dispatch
    response = self.handle_exception(exc)
  File "/home/python/.virtualenvs/gangquan_12/lib/python3.5/site-packages/rest_framework/views.py", line 449, in handle_exception
    exception_handler = self.get_exception_handler()
  File "/home/python/.virtualenvs/gangquan_12/lib/python3.5/site-packages/rest_framework/views.py", line 300, in get_exception_handler
    return self.settings.EXCEPTION_HANDLER
  File "/home/python/.virtualenvs/gangquan_12/lib/python3.5/site-packages/rest_framework/settings.py", line 227, in __getattr__
    val = perform_import(val, attr)
  File "/home/python/.virtualenvs/gangquan_12/lib/python3.5/site-packages/rest_framework/settings.py", line 170, in perform_import
    return import_from_string(val, setting_name)
  File "/home/python/.virtualenvs/gangquan_12/lib/python3.5/site-packages/rest_framework/settings.py", line 187, in import_from_string
    raise ImportError(msg)
ImportError: Could not import 'gangquan_12.utils.exceptions.exception_handler' for API setting 'EXCEPTION_HANDLER'. ImportError: No module named 'gangquan_12.utils.exceptions'.
ERROR 2019-07-01 19:18:41,588 basehttp 124 "GET /sms_codes/15290980528/?text=flgy&image_code_id=83f3b58c-dc44-4713-99b5-acce60e4b904 HTTP/1.1" 500 126611
INFO 2019-07-01 19:19:35,752 basehttp 124 "GET /image_codes/b6d5f129-ccd1-43c5-aeab-e76985c084fa/ HTTP/1.1" 200 2983
INFO 2019-07-01 19:20:23,606 views 74 发送短信验证码(正常) mobile:15290980528
INFO 2019-07-01 19:20:26,979 basehttp 124 "GET /sms_codes/15290980528/?text=hffc&image_code_id=b6d5f129-ccd1-43c5-aeab-e76985c084fa HTTP/1.1" 200 32
INFO 2019-07-01 19:22:37,644 basehttp 124 "GET /image_codes/d18cb6d1-57e2-406b-aacd-f4ec1cb5f426/ HTTP/1.1" 200 3150
INFO 2019-07-01 19:23:46,526 basehttp 124 "GET /image_codes/a11d8783-ebb7-4705-aa4c-e8940eac1e41/ HTTP/1.1" 200 3246
INFO 2019-07-01 19:24:35,886 views 74 发送短信验证码(正常) mobile:15290980528
INFO 2019-07-01 19:24:35,888 basehttp 124 "GET /sms_codes/15290980528/?text=cfze&image_code_id=a11d8783-ebb7-4705-aa4c-e8940eac1e41 HTTP/1.1" 200 32
INFO 2019-07-01 19:27:43,270 basehttp 124 "GET /image_codes/00e378f6-36c0-4f6f-9d52-e889fdeaf628/ HTTP/1.1" 200 2907
INFO 2019-07-01 19:28:14,900 views 76 发送短信验证码(正常) mobile:15290980528
INFO 2019-07-01 19:28:17,763 basehttp 124 "GET /sms_codes/15290980528/?text=pvc6&image_code_id=00e378f6-36c0-4f6f-9d52-e889fdeaf628 HTTP/1.1" 200 32
INFO 2019-07-01 19:31:04,846 basehttp 124 "GET /image_codes/117430bc-1641-49e5-9d9d-e9530e2015f8/ HTTP/1.1" 200 3662
INFO 2019-07-01 19:31:39,079 views 76 发送短信验证码(正常) mobile:15290980528
INFO 2019-07-01 19:31:41,274 basehttp 124 "GET /sms_codes/15290980528/?text=yuhf&image_code_id=117430bc-1641-49e5-9d9d-e9530e2015f8 HTTP/1.1" 200 32
INFO 2019-07-01 19:35:05,640 basehttp 124 "GET /image_codes/9f6777f5-5b6d-4988-a38c-71ade48e4459/ HTTP/1.1" 200 2815
INFO 2019-07-01 19:35:19,614 basehttp 124 "GET /image_codes/2ec50e83-3b34-4614-b152-9cffed9d707d/ HTTP/1.1" 200 3199
INFO 2019-07-01 19:35:28,359 views 76 发送短信验证码(正常) mobile:15290980528
INFO 2019-07-01 19:35:28,360 basehttp 124 "GET /sms_codes/15290980528/?text=y6ke&image_code_id=2ec50e83-3b34-4614-b152-9cffed9d707d HTTP/1.1" 200 32
INFO 2019-07-04 11:04:27,302 basehttp 124 "GET /image_codes/65f3d6bd-c552-4bfd-9ec3-dcfb9d0fe230/ HTTP/1.1" 200 3151
INFO 2019-07-04 11:05:59,289 basehttp 124 "GET /image_codes/b539d854-7784-4b8c-a70f-9b251071d206/ HTTP/1.1" 200 3659
INFO 2019-07-04 11:06:12,327 basehttp 124 "GET /sms_codes/18522222222/?text=GRHE&image_code_id=b539d854-7784-4b8c-a70f-9b251071d206 HTTP/1.1" 200 16
INFO 2019-07-04 11:13:47,260 basehttp 124 "GET /image_codes/0a88a4b1-3717-4a69-ab31-84bab0147abb/ HTTP/1.1" 200 3491
INFO 2019-07-04 11:14:11,934 basehttp 124 "GET /sms_codes/18539022886/?text=7WCL&image_code_id=0a88a4b1-3717-4a69-ab31-84bab0147abb HTTP/1.1" 200 16
INFO 2019-07-04 11:15:56,532 basehttp 124 "GET /image_codes/fcf8c89e-e430-4a95-b3e3-ca85283e74d4/ HTTP/1.1" 200 3052
INFO 2019-07-04 11:16:13,574 basehttp 124 "GET /sms_codes/18539022886/?text=Y8AU&image_code_id=fcf8c89e-e430-4a95-b3e3-ca85283e74d4 HTTP/1.1" 200 16
ERROR 2019-07-04 11:18:52,757 exception 135 Internal Server Error: /sms_codes/18539022886/
Traceback (most recent call last):
  File "/home/python/.virtualenvs/gangquan_12/lib/python3.5/site-packages/rest_framework/views.py", line 492, in dispatch
    response = handler(request, *args, **kwargs)
  File "/home/python/Desktop/gangquanwang/gangquan_12/gangquan_12/apps/verifications/views.py", line 49, in get
    serialzier.is_valid(raise_exception=True)
  File "/home/python/.virtualenvs/gangquan_12/lib/python3.5/site-packages/rest_framework/serializers.py", line 244, in is_valid
    raise ValidationError(self.errors)
rest_framework.exceptions.ValidationError: {'non_field_errors': [ErrorDetail(string='图片验证码无效', code='invalid')]}

During handling of the above exception, another exception occurred:

Traceback (most recent call last):
  File "/home/python/.virtualenvs/gangquan_12/lib/python3.5/site-packages/rest_framework/settings.py", line 183, in import_from_string
    module = import_module(module_path)
  File "/home/python/.virtualenvs/gangquan_12/lib/python3.5/importlib/__init__.py", line 126, in import_module
    return _bootstrap._gcd_import(name[level:], package, level)
  File "<frozen importlib._bootstrap>", line 986, in _gcd_import
  File "<frozen importlib._bootstrap>", line 969, in _find_and_load
  File "<frozen importlib._bootstrap>", line 956, in _find_and_load_unlocked
ImportError: No module named 'gangquan_12.utils.exceptions'

During handling of the above exception, another exception occurred:

Traceback (most recent call last):
  File "/home/python/.virtualenvs/gangquan_12/lib/python3.5/site-packages/django/core/handlers/exception.py", line 41, in inner
    response = get_response(request)
  File "/home/python/.virtualenvs/gangquan_12/lib/python3.5/site-packages/django/core/handlers/base.py", line 187, in _get_response
    response = self.process_exception_by_middleware(e, request)
  File "/home/python/.virtualenvs/gangquan_12/lib/python3.5/site-packages/django/core/handlers/base.py", line 185, in _get_response
    response = wrapped_callback(request, *callback_args, **callback_kwargs)
  File "/home/python/.virtualenvs/gangquan_12/lib/python3.5/site-packages/django/views/decorators/csrf.py", line 58, in wrapped_view
    return view_func(*args, **kwargs)
  File "/home/python/.virtualenvs/gangquan_12/lib/python3.5/site-packages/django/views/generic/base.py", line 68, in view
    return self.dispatch(request, *args, **kwargs)
  File "/home/python/.virtualenvs/gangquan_12/lib/python3.5/site-packages/rest_framework/views.py", line 495, in dispatch
    response = self.handle_exception(exc)
  File "/home/python/.virtualenvs/gangquan_12/lib/python3.5/site-packages/rest_framework/views.py", line 449, in handle_exception
    exception_handler = self.get_exception_handler()
  File "/home/python/.virtualenvs/gangquan_12/lib/python3.5/site-packages/rest_framework/views.py", line 300, in get_exception_handler
    return self.settings.EXCEPTION_HANDLER
  File "/home/python/.virtualenvs/gangquan_12/lib/python3.5/site-packages/rest_framework/settings.py", line 227, in __getattr__
    val = perform_import(val, attr)
  File "/home/python/.virtualenvs/gangquan_12/lib/python3.5/site-packages/rest_framework/settings.py", line 170, in perform_import
    return import_from_string(val, setting_name)
  File "/home/python/.virtualenvs/gangquan_12/lib/python3.5/site-packages/rest_framework/settings.py", line 187, in import_from_string
    raise ImportError(msg)
ImportError: Could not import 'gangquan_12.utils.exceptions.exception_handler' for API setting 'EXCEPTION_HANDLER'. ImportError: No module named 'gangquan_12.utils.exceptions'.
ERROR 2019-07-04 11:18:53,003 basehttp 124 "GET /sms_codes/18539022886/?text=Y8AU&image_code_id=fcf8c89e-e430-4a95-b3e3-ca85283e74d4 HTTP/1.1" 500 127160
ERROR 2019-07-04 11:18:57,342 exception 135 Internal Server Error: /sms_codes/18539022886/
Traceback (most recent call last):
  File "/home/python/.virtualenvs/gangquan_12/lib/python3.5/site-packages/rest_framework/views.py", line 492, in dispatch
    response = handler(request, *args, **kwargs)
  File "/home/python/Desktop/gangquanwang/gangquan_12/gangquan_12/apps/verifications/views.py", line 49, in get
    serialzier.is_valid(raise_exception=True)
  File "/home/python/.virtualenvs/gangquan_12/lib/python3.5/site-packages/rest_framework/serializers.py", line 244, in is_valid
    raise ValidationError(self.errors)
rest_framework.exceptions.ValidationError: {'non_field_errors': [ErrorDetail(string='图片验证码无效', code='invalid')]}

During handling of the above exception, another exception occurred:

Traceback (most recent call last):
  File "/home/python/.virtualenvs/gangquan_12/lib/python3.5/site-packages/rest_framework/settings.py", line 183, in import_from_string
    module = import_module(module_path)
  File "/home/python/.virtualenvs/gangquan_12/lib/python3.5/importlib/__init__.py", line 126, in import_module
    return _bootstrap._gcd_import(name[level:], package, level)
  File "<frozen importlib._bootstrap>", line 986, in _gcd_import
  File "<frozen importlib._bootstrap>", line 969, in _find_and_load
  File "<frozen importlib._bootstrap>", line 956, in _find_and_load_unlocked
ImportError: No module named 'gangquan_12.utils.exceptions'

During handling of the above exception, another exception occurred:

Traceback (most recent call last):
  File "/home/python/.virtualenvs/gangquan_12/lib/python3.5/site-packages/django/core/handlers/exception.py", line 41, in inner
    response = get_response(request)
  File "/home/python/.virtualenvs/gangquan_12/lib/python3.5/site-packages/django/core/handlers/base.py", line 187, in _get_response
    response = self.process_exception_by_middleware(e, request)
  File "/home/python/.virtualenvs/gangquan_12/lib/python3.5/site-packages/django/core/handlers/base.py", line 185, in _get_response
    response = wrapped_callback(request, *callback_args, **callback_kwargs)
  File "/home/python/.virtualenvs/gangquan_12/lib/python3.5/site-packages/django/views/decorators/csrf.py", line 58, in wrapped_view
    return view_func(*args, **kwargs)
  File "/home/python/.virtualenvs/gangquan_12/lib/python3.5/site-packages/django/views/generic/base.py", line 68, in view
    return self.dispatch(request, *args, **kwargs)
  File "/home/python/.virtualenvs/gangquan_12/lib/python3.5/site-packages/rest_framework/views.py", line 495, in dispatch
    response = self.handle_exception(exc)
  File "/home/python/.virtualenvs/gangquan_12/lib/python3.5/site-packages/rest_framework/views.py", line 449, in handle_exception
    exception_handler = self.get_exception_handler()
  File "/home/python/.virtualenvs/gangquan_12/lib/python3.5/site-packages/rest_framework/views.py", line 300, in get_exception_handler
    return self.settings.EXCEPTION_HANDLER
  File "/home/python/.virtualenvs/gangquan_12/lib/python3.5/site-packages/rest_framework/settings.py", line 227, in __getattr__
    val = perform_import(val, attr)
  File "/home/python/.virtualenvs/gangquan_12/lib/python3.5/site-packages/rest_framework/settings.py", line 170, in perform_import
    return import_from_string(val, setting_name)
  File "/home/python/.virtualenvs/gangquan_12/lib/python3.5/site-packages/rest_framework/settings.py", line 187, in import_from_string
    raise ImportError(msg)
ImportError: Could not import 'gangquan_12.utils.exceptions.exception_handler' for API setting 'EXCEPTION_HANDLER'. ImportError: No module named 'gangquan_12.utils.exceptions'.
ERROR 2019-07-04 11:18:57,428 basehttp 124 "GET /sms_codes/18539022886/?text=Y8AU&image_code_id=fcf8c89e-e430-4a95-b3e3-ca85283e74d4 HTTP/1.1" 500 127160
INFO 2019-07-04 15:36:44,361 basehttp 124 "GET /image_codes/a26e75d6-9112-408a-b4b8-cb42e8ed5d7e/ HTTP/1.1" 200 2939
INFO 2019-07-04 15:39:00,567 basehttp 124 "GET /sms_codes/18522222222/?text=ISDP&image_code_id=a26e75d6-9112-408a-b4b8-cb42e8ed5d7e HTTP/1.1" 200 16
INFO 2019-07-04 15:39:10,275 basehttp 124 "OPTIONS /users/ HTTP/1.1" 200 0
ERROR 2019-07-04 15:39:10,279 exception 135 Internal Server Error: /users/
Traceback (most recent call last):
  File "/home/python/.virtualenvs/gangquan_12/lib/python3.5/site-packages/rest_framework/views.py", line 492, in dispatch
    response = handler(request, *args, **kwargs)
  File "/home/python/.virtualenvs/gangquan_12/lib/python3.5/site-packages/rest_framework/generics.py", line 192, in post
    return self.create(request, *args, **kwargs)
  File "/home/python/.virtualenvs/gangquan_12/lib/python3.5/site-packages/rest_framework/mixins.py", line 20, in create
    serializer.is_valid(raise_exception=True)
  File "/home/python/.virtualenvs/gangquan_12/lib/python3.5/site-packages/rest_framework/serializers.py", line 236, in is_valid
    self._validated_data = self.run_validation(self.initial_data)
  File "/home/python/.virtualenvs/gangquan_12/lib/python3.5/site-packages/rest_framework/serializers.py", line 434, in run_validation
    value = self.to_internal_value(data)
  File "/home/python/.virtualenvs/gangquan_12/lib/python3.5/site-packages/rest_framework/serializers.py", line 485, in to_internal_value
    fields = self._writable_fields
  File "/home/python/.virtualenvs/gangquan_12/lib/python3.5/site-packages/django/utils/functional.py", line 35, in __get__
    res = instance.__dict__[self.name] = self.func(instance)
  File "/home/python/.virtualenvs/gangquan_12/lib/python3.5/site-packages/rest_framework/serializers.py", line 370, in _writable_fields
    field for field in self.fields.values() if not field.read_only
  File "/home/python/.virtualenvs/gangquan_12/lib/python3.5/site-packages/rest_framework/serializers.py", line 363, in fields
    for key, value in self.get_fields().items():
  File "/home/python/.virtualenvs/gangquan_12/lib/python3.5/site-packages/rest_framework/serializers.py", line 1059, in get_fields
    fields[field_name] = field_class(**field_kwargs)
  File "/home/python/.virtualenvs/gangquan_12/lib/python3.5/site-packages/rest_framework/fields.py", line 767, in __init__
    super(CharField, self).__init__(**kwargs)
TypeError: __init__() got an unexpected keyword argument 'error_message'

During handling of the above exception, another exception occurred:

Traceback (most recent call last):
  File "/home/python/.virtualenvs/gangquan_12/lib/python3.5/site-packages/rest_framework/settings.py", line 183, in import_from_string
    module = import_module(module_path)
  File "/home/python/.virtualenvs/gangquan_12/lib/python3.5/importlib/__init__.py", line 126, in import_module
    return _bootstrap._gcd_import(name[level:], package, level)
  File "<frozen importlib._bootstrap>", line 986, in _gcd_import
  File "<frozen importlib._bootstrap>", line 969, in _find_and_load
  File "<frozen importlib._bootstrap>", line 956, in _find_and_load_unlocked
ImportError: No module named 'gangquan_12.utils.exceptions'

During handling of the above exception, another exception occurred:

Traceback (most recent call last):
  File "/home/python/.virtualenvs/gangquan_12/lib/python3.5/site-packages/django/core/handlers/exception.py", line 41, in inner
    response = get_response(request)
  File "/home/python/.virtualenvs/gangquan_12/lib/python3.5/site-packages/django/core/handlers/base.py", line 187, in _get_response
    response = self.process_exception_by_middleware(e, request)
  File "/home/python/.virtualenvs/gangquan_12/lib/python3.5/site-packages/django/core/handlers/base.py", line 185, in _get_response
    response = wrapped_callback(request, *callback_args, **callback_kwargs)
  File "/home/python/.virtualenvs/gangquan_12/lib/python3.5/site-packages/django/views/decorators/csrf.py", line 58, in wrapped_view
    return view_func(*args, **kwargs)
  File "/home/python/.virtualenvs/gangquan_12/lib/python3.5/site-packages/django/views/generic/base.py", line 68, in view
    return self.dispatch(request, *args, **kwargs)
  File "/home/python/.virtualenvs/gangquan_12/lib/python3.5/site-packages/rest_framework/views.py", line 495, in dispatch
    response = self.handle_exception(exc)
  File "/home/python/.virtualenvs/gangquan_12/lib/python3.5/site-packages/rest_framework/views.py", line 449, in handle_exception
    exception_handler = self.get_exception_handler()
  File "/home/python/.virtualenvs/gangquan_12/lib/python3.5/site-packages/rest_framework/views.py", line 300, in get_exception_handler
    return self.settings.EXCEPTION_HANDLER
  File "/home/python/.virtualenvs/gangquan_12/lib/python3.5/site-packages/rest_framework/settings.py", line 227, in __getattr__
    val = perform_import(val, attr)
  File "/home/python/.virtualenvs/gangquan_12/lib/python3.5/site-packages/rest_framework/settings.py", line 170, in perform_import
    return import_from_string(val, setting_name)
  File "/home/python/.virtualenvs/gangquan_12/lib/python3.5/site-packages/rest_framework/settings.py", line 187, in import_from_string
    raise ImportError(msg)
ImportError: Could not import 'gangquan_12.utils.exceptions.exception_handler' for API setting 'EXCEPTION_HANDLER'. ImportError: No module named 'gangquan_12.utils.exceptions'.
ERROR 2019-07-04 15:39:10,506 basehttp 124 "POST /users/ HTTP/1.1" 500 168874
INFO 2019-07-04 15:52:30,064 basehttp 124 "OPTIONS /users/ HTTP/1.1" 200 0
ERROR 2019-07-04 15:52:30,075 exception 135 Internal Server Error: /users/
Traceback (most recent call last):
  File "/home/python/.virtualenvs/gangquan_12/lib/python3.5/site-packages/rest_framework/views.py", line 492, in dispatch
    response = handler(request, *args, **kwargs)
  File "/home/python/.virtualenvs/gangquan_12/lib/python3.5/site-packages/rest_framework/generics.py", line 192, in post
    return self.create(request, *args, **kwargs)
  File "/home/python/.virtualenvs/gangquan_12/lib/python3.5/site-packages/rest_framework/mixins.py", line 20, in create
    serializer.is_valid(raise_exception=True)
  File "/home/python/.virtualenvs/gangquan_12/lib/python3.5/site-packages/rest_framework/serializers.py", line 236, in is_valid
    self._validated_data = self.run_validation(self.initial_data)
  File "/home/python/.virtualenvs/gangquan_12/lib/python3.5/site-packages/rest_framework/serializers.py", line 434, in run_validation
    value = self.to_internal_value(data)
  File "/home/python/.virtualenvs/gangquan_12/lib/python3.5/site-packages/rest_framework/serializers.py", line 485, in to_internal_value
    fields = self._writable_fields
  File "/home/python/.virtualenvs/gangquan_12/lib/python3.5/site-packages/django/utils/functional.py", line 35, in __get__
    res = instance.__dict__[self.name] = self.func(instance)
  File "/home/python/.virtualenvs/gangquan_12/lib/python3.5/site-packages/rest_framework/serializers.py", line 370, in _writable_fields
    field for field in self.fields.values() if not field.read_only
  File "/home/python/.virtualenvs/gangquan_12/lib/python3.5/site-packages/rest_framework/serializers.py", line 363, in fields
    for key, value in self.get_fields().items():
  File "/home/python/.virtualenvs/gangquan_12/lib/python3.5/site-packages/rest_framework/serializers.py", line 1059, in get_fields
    fields[field_name] = field_class(**field_kwargs)
  File "/home/python/.virtualenvs/gangquan_12/lib/python3.5/site-packages/rest_framework/fields.py", line 767, in __init__
    super(CharField, self).__init__(**kwargs)
TypeError: __init__() got an unexpected keyword argument 'error_message'

During handling of the above exception, another exception occurred:

Traceback (most recent call last):
  File "/home/python/.virtualenvs/gangquan_12/lib/python3.5/site-packages/rest_framework/settings.py", line 183, in import_from_string
    module = import_module(module_path)
  File "/home/python/.virtualenvs/gangquan_12/lib/python3.5/importlib/__init__.py", line 126, in import_module
    return _bootstrap._gcd_import(name[level:], package, level)
  File "<frozen importlib._bootstrap>", line 986, in _gcd_import
  File "<frozen importlib._bootstrap>", line 969, in _find_and_load
  File "<frozen importlib._bootstrap>", line 956, in _find_and_load_unlocked
ImportError: No module named 'gangquan_12.utils.exceptions'

During handling of the above exception, another exception occurred:

Traceback (most recent call last):
  File "/home/python/.virtualenvs/gangquan_12/lib/python3.5/site-packages/django/core/handlers/exception.py", line 41, in inner
    response = get_response(request)
  File "/home/python/.virtualenvs/gangquan_12/lib/python3.5/site-packages/django/core/handlers/base.py", line 187, in _get_response
    response = self.process_exception_by_middleware(e, request)
  File "/home/python/.virtualenvs/gangquan_12/lib/python3.5/site-packages/django/core/handlers/base.py", line 185, in _get_response
    response = wrapped_callback(request, *callback_args, **callback_kwargs)
  File "/home/python/.virtualenvs/gangquan_12/lib/python3.5/site-packages/django/views/decorators/csrf.py", line 58, in wrapped_view
    return view_func(*args, **kwargs)
  File "/home/python/.virtualenvs/gangquan_12/lib/python3.5/site-packages/django/views/generic/base.py", line 68, in view
    return self.dispatch(request, *args, **kwargs)
  File "/home/python/.virtualenvs/gangquan_12/lib/python3.5/site-packages/rest_framework/views.py", line 495, in dispatch
    response = self.handle_exception(exc)
  File "/home/python/.virtualenvs/gangquan_12/lib/python3.5/site-packages/rest_framework/views.py", line 449, in handle_exception
    exception_handler = self.get_exception_handler()
  File "/home/python/.virtualenvs/gangquan_12/lib/python3.5/site-packages/rest_framework/views.py", line 300, in get_exception_handler
    return self.settings.EXCEPTION_HANDLER
  File "/home/python/.virtualenvs/gangquan_12/lib/python3.5/site-packages/rest_framework/settings.py", line 227, in __getattr__
    val = perform_import(val, attr)
  File "/home/python/.virtualenvs/gangquan_12/lib/python3.5/site-packages/rest_framework/settings.py", line 170, in perform_import
    return import_from_string(val, setting_name)
  File "/home/python/.virtualenvs/gangquan_12/lib/python3.5/site-packages/rest_framework/settings.py", line 187, in import_from_string
    raise ImportError(msg)
ImportError: Could not import 'gangquan_12.utils.exceptions.exception_handler' for API setting 'EXCEPTION_HANDLER'. ImportError: No module named 'gangquan_12.utils.exceptions'.
ERROR 2019-07-04 15:52:30,535 basehttp 124 "POST /users/ HTTP/1.1" 500 168874
INFO 2019-07-04 15:53:56,551 basehttp 124 "GET /image_codes/929abbdb-fa0c-4eed-998c-65ad7acd39e4/ HTTP/1.1" 200 3219
INFO 2019-07-04 15:54:17,526 basehttp 124 "GET /sms_codes/18522222222/?text=FACG&image_code_id=929abbdb-fa0c-4eed-998c-65ad7acd39e4 HTTP/1.1" 200 16
ERROR 2019-07-04 15:54:28,029 exception 135 Internal Server Error: /users/
Traceback (most recent call last):
  File "/home/python/.virtualenvs/gangquan_12/lib/python3.5/site-packages/django/core/handlers/exception.py", line 41, in inner
    response = get_response(request)
  File "/home/python/.virtualenvs/gangquan_12/lib/python3.5/site-packages/django/core/handlers/base.py", line 187, in _get_response
    response = self.process_exception_by_middleware(e, request)
  File "/home/python/.virtualenvs/gangquan_12/lib/python3.5/site-packages/django/core/handlers/base.py", line 185, in _get_response
    response = wrapped_callback(request, *callback_args, **callback_kwargs)
  File "/home/python/.virtualenvs/gangquan_12/lib/python3.5/site-packages/django/views/decorators/csrf.py", line 58, in wrapped_view
    return view_func(*args, **kwargs)
  File "/home/python/.virtualenvs/gangquan_12/lib/python3.5/site-packages/django/views/generic/base.py", line 68, in view
    return self.dispatch(request, *args, **kwargs)
  File "/home/python/.virtualenvs/gangquan_12/lib/python3.5/site-packages/rest_framework/views.py", line 495, in dispatch
    response = self.handle_exception(exc)
  File "/home/python/.virtualenvs/gangquan_12/lib/python3.5/site-packages/rest_framework/views.py", line 455, in handle_exception
    self.raise_uncaught_exception(exc)
  File "/home/python/.virtualenvs/gangquan_12/lib/python3.5/site-packages/rest_framework/views.py", line 492, in dispatch
    response = handler(request, *args, **kwargs)
  File "/home/python/.virtualenvs/gangquan_12/lib/python3.5/site-packages/rest_framework/generics.py", line 192, in post
    return self.create(request, *args, **kwargs)
  File "/home/python/.virtualenvs/gangquan_12/lib/python3.5/site-packages/rest_framework/mixins.py", line 20, in create
    serializer.is_valid(raise_exception=True)
  File "/home/python/.virtualenvs/gangquan_12/lib/python3.5/site-packages/rest_framework/serializers.py", line 236, in is_valid
    self._validated_data = self.run_validation(self.initial_data)
  File "/home/python/.virtualenvs/gangquan_12/lib/python3.5/site-packages/rest_framework/serializers.py", line 434, in run_validation
    value = self.to_internal_value(data)
  File "/home/python/.virtualenvs/gangquan_12/lib/python3.5/site-packages/rest_framework/serializers.py", line 485, in to_internal_value
    fields = self._writable_fields
  File "/home/python/.virtualenvs/gangquan_12/lib/python3.5/site-packages/django/utils/functional.py", line 35, in __get__
    res = instance.__dict__[self.name] = self.func(instance)
  File "/home/python/.virtualenvs/gangquan_12/lib/python3.5/site-packages/rest_framework/serializers.py", line 370, in _writable_fields
    field for field in self.fields.values() if not field.read_only
  File "/home/python/.virtualenvs/gangquan_12/lib/python3.5/site-packages/rest_framework/serializers.py", line 363, in fields
    for key, value in self.get_fields().items():
  File "/home/python/.virtualenvs/gangquan_12/lib/python3.5/site-packages/rest_framework/serializers.py", line 1059, in get_fields
    fields[field_name] = field_class(**field_kwargs)
  File "/home/python/.virtualenvs/gangquan_12/lib/python3.5/site-packages/rest_framework/fields.py", line 767, in __init__
    super(CharField, self).__init__(**kwargs)
TypeError: __init__() got an unexpected keyword argument 'error_message'
ERROR 2019-07-04 15:54:28,060 basehttp 124 "POST /users/ HTTP/1.1" 500 19584
INFO 2019-07-04 16:28:29,303 basehttp 124 "GET /image_codes/f5d9a0d7-fcb4-4f55-8c5d-6e7f25197010/ HTTP/1.1" 200 3362
INFO 2019-07-04 16:28:52,687 basehttp 124 "GET /sms_codes/18522222222/?text=MK6Q&image_code_id=f5d9a0d7-fcb4-4f55-8c5d-6e7f25197010 HTTP/1.1" 200 16
INFO 2019-07-04 16:29:03,413 basehttp 124 "OPTIONS /users/ HTTP/1.1" 200 0
ERROR 2019-07-04 16:29:03,645 exception 135 Internal Server Error: /users/
Traceback (most recent call last):
  File "/home/python/.virtualenvs/gangquan_12/lib/python3.5/site-packages/django/core/handlers/exception.py", line 41, in inner
    response = get_response(request)
  File "/home/python/.virtualenvs/gangquan_12/lib/python3.5/site-packages/django/core/handlers/base.py", line 187, in _get_response
    response = self.process_exception_by_middleware(e, request)
  File "/home/python/.virtualenvs/gangquan_12/lib/python3.5/site-packages/django/core/handlers/base.py", line 185, in _get_response
    response = wrapped_callback(request, *callback_args, **callback_kwargs)
  File "/home/python/.virtualenvs/gangquan_12/lib/python3.5/site-packages/django/views/decorators/csrf.py", line 58, in wrapped_view
    return view_func(*args, **kwargs)
  File "/home/python/.virtualenvs/gangquan_12/lib/python3.5/site-packages/django/views/generic/base.py", line 68, in view
    return self.dispatch(request, *args, **kwargs)
  File "/home/python/.virtualenvs/gangquan_12/lib/python3.5/site-packages/rest_framework/views.py", line 495, in dispatch
    response = self.handle_exception(exc)
  File "/home/python/.virtualenvs/gangquan_12/lib/python3.5/site-packages/rest_framework/views.py", line 455, in handle_exception
    self.raise_uncaught_exception(exc)
  File "/home/python/.virtualenvs/gangquan_12/lib/python3.5/site-packages/rest_framework/views.py", line 492, in dispatch
    response = handler(request, *args, **kwargs)
  File "/home/python/.virtualenvs/gangquan_12/lib/python3.5/site-packages/rest_framework/generics.py", line 192, in post
    return self.create(request, *args, **kwargs)
  File "/home/python/.virtualenvs/gangquan_12/lib/python3.5/site-packages/rest_framework/mixins.py", line 20, in create
    serializer.is_valid(raise_exception=True)
  File "/home/python/.virtualenvs/gangquan_12/lib/python3.5/site-packages/rest_framework/serializers.py", line 236, in is_valid
    self._validated_data = self.run_validation(self.initial_data)
  File "/home/python/.virtualenvs/gangquan_12/lib/python3.5/site-packages/rest_framework/serializers.py", line 437, in run_validation
    value = self.validate(value)
  File "/home/python/Desktop/gangquanwang/gangquan_12/gangquan_12/apps/users/serializers.py", line 56, in validate
    redis_conn = get_redis_connection('verify')
  File "/home/python/.virtualenvs/gangquan_12/lib/python3.5/site-packages/django_redis/__init__.py", line 14, in get_redis_connection
    cache = caches[alias]
  File "/home/python/.virtualenvs/gangquan_12/lib/python3.5/site-packages/django/core/cache/__init__.py", line 77, in __getitem__
    "Could not find config for '%s' in settings.CACHES" % alias
django.core.cache.backends.base.InvalidCacheBackendError: Could not find config for 'verify' in settings.CACHES
ERROR 2019-07-04 16:29:03,726 basehttp 124 "POST /users/ HTTP/1.1" 500 19019
INFO 2019-07-04 16:29:57,398 basehttp 124 "GET /image_codes/210addde-271c-4a54-9803-bc43abef0203/ HTTP/1.1" 200 3222
INFO 2019-07-04 16:30:05,853 basehttp 124 "GET /image_codes/d858e9cc-b0fb-4b12-8f59-878818f6114a/ HTTP/1.1" 200 2781
INFO 2019-07-04 16:30:25,033 basehttp 124 "GET /sms_codes/18522222222/?text=7AEJ&image_code_id=d858e9cc-b0fb-4b12-8f59-878818f6114a HTTP/1.1" 200 16
ERROR 2019-07-04 16:30:34,775 exception 135 Internal Server Error: /users/
Traceback (most recent call last):
  File "/home/python/.virtualenvs/gangquan_12/lib/python3.5/site-packages/django/core/handlers/exception.py", line 41, in inner
    response = get_response(request)
  File "/home/python/.virtualenvs/gangquan_12/lib/python3.5/site-packages/django/core/handlers/base.py", line 187, in _get_response
    response = self.process_exception_by_middleware(e, request)
  File "/home/python/.virtualenvs/gangquan_12/lib/python3.5/site-packages/django/core/handlers/base.py", line 185, in _get_response
    response = wrapped_callback(request, *callback_args, **callback_kwargs)
  File "/home/python/.virtualenvs/gangquan_12/lib/python3.5/site-packages/django/views/decorators/csrf.py", line 58, in wrapped_view
    return view_func(*args, **kwargs)
  File "/home/python/.virtualenvs/gangquan_12/lib/python3.5/site-packages/django/views/generic/base.py", line 68, in view
    return self.dispatch(request, *args, **kwargs)
  File "/home/python/.virtualenvs/gangquan_12/lib/python3.5/site-packages/rest_framework/views.py", line 495, in dispatch
    response = self.handle_exception(exc)
  File "/home/python/.virtualenvs/gangquan_12/lib/python3.5/site-packages/rest_framework/views.py", line 455, in handle_exception
    self.raise_uncaught_exception(exc)
  File "/home/python/.virtualenvs/gangquan_12/lib/python3.5/site-packages/rest_framework/views.py", line 492, in dispatch
    response = handler(request, *args, **kwargs)
  File "/home/python/.virtualenvs/gangquan_12/lib/python3.5/site-packages/rest_framework/generics.py", line 192, in post
    return self.create(request, *args, **kwargs)
  File "/home/python/.virtualenvs/gangquan_12/lib/python3.5/site-packages/rest_framework/mixins.py", line 20, in create
    serializer.is_valid(raise_exception=True)
  File "/home/python/.virtualenvs/gangquan_12/lib/python3.5/site-packages/rest_framework/serializers.py", line 236, in is_valid
    self._validated_data = self.run_validation(self.initial_data)
  File "/home/python/.virtualenvs/gangquan_12/lib/python3.5/site-packages/rest_framework/serializers.py", line 437, in run_validation
    value = self.validate(value)
  File "/home/python/Desktop/gangquanwang/gangquan_12/gangquan_12/apps/users/serializers.py", line 58, in validate
    if real_sms_code.decode() != attrs['sms_code']:
AttributeError: 'NoneType' object has no attribute 'decode'
ERROR 2019-07-04 16:30:34,803 basehttp 124 "POST /users/ HTTP/1.1" 500 18627
INFO 2019-07-04 17:36:52,868 basehttp 124 "GET /image_codes/1973ee50-5d38-402f-b83a-e069471458a9/ HTTP/1.1" 200 3315
INFO 2019-07-04 17:37:12,773 basehttp 124 "GET /sms_codes/18522222222/?text=MUXT&image_code_id=1973ee50-5d38-402f-b83a-e069471458a9 HTTP/1.1" 200 16
INFO 2019-07-04 17:37:22,873 basehttp 124 "OPTIONS /users/ HTTP/1.1" 200 0
ERROR 2019-07-04 17:37:22,886 exception 135 Internal Server Error: /users/
Traceback (most recent call last):
  File "/home/python/.virtualenvs/gangquan_12/lib/python3.5/site-packages/django/core/handlers/exception.py", line 41, in inner
    response = get_response(request)
  File "/home/python/.virtualenvs/gangquan_12/lib/python3.5/site-packages/django/core/handlers/base.py", line 187, in _get_response
    response = self.process_exception_by_middleware(e, request)
  File "/home/python/.virtualenvs/gangquan_12/lib/python3.5/site-packages/django/core/handlers/base.py", line 185, in _get_response
    response = wrapped_callback(request, *callback_args, **callback_kwargs)
  File "/home/python/.virtualenvs/gangquan_12/lib/python3.5/site-packages/django/views/decorators/csrf.py", line 58, in wrapped_view
    return view_func(*args, **kwargs)
  File "/home/python/.virtualenvs/gangquan_12/lib/python3.5/site-packages/django/views/generic/base.py", line 68, in view
    return self.dispatch(request, *args, **kwargs)
  File "/home/python/.virtualenvs/gangquan_12/lib/python3.5/site-packages/rest_framework/views.py", line 495, in dispatch
    response = self.handle_exception(exc)
  File "/home/python/.virtualenvs/gangquan_12/lib/python3.5/site-packages/rest_framework/views.py", line 455, in handle_exception
    self.raise_uncaught_exception(exc)
  File "/home/python/.virtualenvs/gangquan_12/lib/python3.5/site-packages/rest_framework/views.py", line 492, in dispatch
    response = handler(request, *args, **kwargs)
  File "/home/python/.virtualenvs/gangquan_12/lib/python3.5/site-packages/rest_framework/generics.py", line 192, in post
    return self.create(request, *args, **kwargs)
  File "/home/python/.virtualenvs/gangquan_12/lib/python3.5/site-packages/rest_framework/mixins.py", line 20, in create
    serializer.is_valid(raise_exception=True)
  File "/home/python/.virtualenvs/gangquan_12/lib/python3.5/site-packages/rest_framework/serializers.py", line 236, in is_valid
    self._validated_data = self.run_validation(self.initial_data)
  File "/home/python/.virtualenvs/gangquan_12/lib/python3.5/site-packages/rest_framework/serializers.py", line 438, in run_validation
    assert value is not None, '.validate() should return the validated data'
AssertionError: .validate() should return the validated data
ERROR 2019-07-04 17:37:22,912 basehttp 124 "POST /users/ HTTP/1.1" 500 18507
INFO 2019-07-04 18:16:07,460 basehttp 124 "GET /image_codes/6f0ea192-5a5c-4e8c-8953-8b764e1f1aac/ HTTP/1.1" 200 3010
INFO 2019-07-04 18:16:08,967 basehttp 124 "GET /image_codes/caa99fcf-4f9a-4c27-9da3-ca8587c11962/ HTTP/1.1" 200 3069
INFO 2019-07-04 18:16:38,211 basehttp 124 "GET /sms_codes/18522222222/?text=LNJH&image_code_id=caa99fcf-4f9a-4c27-9da3-ca8587c11962 HTTP/1.1" 200 16
INFO 2019-07-04 18:16:47,143 basehttp 124 "OPTIONS /users/ HTTP/1.1" 200 0
INFO 2019-07-04 18:16:47,677 basehttp 124 "POST /users/ HTTP/1.1" 201 51
INFO 2019-07-04 18:24:13,120 basehttp 124 "GET /image_codes/ec54861c-ea66-4e58-a3bd-19620ca6fa5a/ HTTP/1.1" 200 3386
INFO 2019-07-04 18:26:58,321 basehttp 124 "GET /image_codes/81a74260-6d31-4cbd-a013-382f232e2bd2/ HTTP/1.1" 200 3366
INFO 2019-07-04 18:27:02,347 basehttp 124 "GET /image_codes/2bad7ce0-426a-4d96-b782-fa410a3cc7ea/ HTTP/1.1" 200 3080
WARNING 2019-07-04 18:27:09,253 base 152 Not Found: /usernames/python1/count/
WARNING 2019-07-04 18:27:09,254 basehttp 124 "GET /usernames/python1/count/ HTTP/1.1" 404 2922
INFO 2019-07-04 18:28:08,742 basehttp 124 "GET /image_codes/5fabfa39-7606-4b6e-aa08-ddc21822d7d1/ HTTP/1.1" 200 3479
WARNING 2019-07-04 18:28:12,127 base 152 Not Found: /usernames/python1/count/
WARNING 2019-07-04 18:28:12,127 basehttp 124 "GET /usernames/python1/count/ HTTP/1.1" 404 2927
INFO 2019-07-04 18:29:41,967 basehttp 124 "GET /image_codes/decc76d0-0e57-4697-86ba-b66e5ae502da/ HTTP/1.1" 200 3247
ERROR 2019-07-04 18:29:46,944 exception 135 Internal Server Error: /usernames/python1/count/
Traceback (most recent call last):
  File "/home/python/.virtualenvs/gangquan_12/lib/python3.5/site-packages/django/core/handlers/exception.py", line 41, in inner
    response = get_response(request)
  File "/home/python/.virtualenvs/gangquan_12/lib/python3.5/site-packages/django/core/handlers/base.py", line 187, in _get_response
    response = self.process_exception_by_middleware(e, request)
  File "/home/python/.virtualenvs/gangquan_12/lib/python3.5/site-packages/django/core/handlers/base.py", line 185, in _get_response
    response = wrapped_callback(request, *callback_args, **callback_kwargs)
  File "/home/python/.virtualenvs/gangquan_12/lib/python3.5/site-packages/django/views/decorators/csrf.py", line 58, in wrapped_view
    return view_func(*args, **kwargs)
  File "/home/python/.virtualenvs/gangquan_12/lib/python3.5/site-packages/django/views/generic/base.py", line 68, in view
    return self.dispatch(request, *args, **kwargs)
  File "/home/python/.virtualenvs/gangquan_12/lib/python3.5/site-packages/rest_framework/views.py", line 495, in dispatch
    response = self.handle_exception(exc)
  File "/home/python/.virtualenvs/gangquan_12/lib/python3.5/site-packages/rest_framework/views.py", line 455, in handle_exception
    self.raise_uncaught_exception(exc)
  File "/home/python/.virtualenvs/gangquan_12/lib/python3.5/site-packages/rest_framework/views.py", line 492, in dispatch
    response = handler(request, *args, **kwargs)
  File "/home/python/Desktop/gangquanwang/gangquan_12/gangquan_12/apps/users/views.py", line 26, in get
    count = User.objects.get(username=username).count()
  File "/home/python/.virtualenvs/gangquan_12/lib/python3.5/site-packages/django/db/models/manager.py", line 85, in manager_method
    return getattr(self.get_queryset(), name)(*args, **kwargs)
  File "/home/python/.virtualenvs/gangquan_12/lib/python3.5/site-packages/django/db/models/query.py", line 380, in get
    self.model._meta.object_name
users.models.DoesNotExist: User matching query does not exist.
ERROR 2019-07-04 18:29:47,019 basehttp 124 "GET /usernames/python1/count/ HTTP/1.1" 500 18302
INFO 2019-07-04 18:30:50,993 basehttp 124 "GET /image_codes/b78bd49a-54aa-439a-aa91-9b7a6776b5ce/ HTTP/1.1" 200 3035
INFO 2019-07-04 18:30:55,044 basehttp 124 "GET /usernames/python1/count/ HTTP/1.1" 200 32
WARNING 2019-07-04 18:31:13,570 base 152 Not Found: /mobiles/18511111111/count/
WARNING 2019-07-04 18:31:13,571 basehttp 124 "GET /mobiles/18511111111/count/ HTTP/1.1" 404 2935
INFO 2019-07-04 18:31:30,612 basehttp 124 "GET /image_codes/29bf1883-4b16-4467-8804-d1c362e40a5a/ HTTP/1.1" 200 3317
INFO 2019-07-04 18:31:33,894 basehttp 124 "GET /usernames/python1/count/ HTTP/1.1" 200 32
INFO 2019-07-04 18:31:42,561 basehttp 124 "GET /mobiles/18511111111/count/ HTTP/1.1" 200 34
INFO 2019-07-04 18:32:03,252 basehttp 124 "GET /mobiles/18511111111/count/ HTTP/1.1" 200 34
INFO 2019-07-04 18:32:03,310 basehttp 124 "GET /sms_codes/18511111111/?text=OAVT&image_code_id=29bf1883-4b16-4467-8804-d1c362e40a5a HTTP/1.1" 200 16
INFO 2019-07-04 18:32:19,662 basehttp 124 "OPTIONS /users/ HTTP/1.1" 200 0
INFO 2019-07-04 18:32:20,121 basehttp 124 "GET /mobiles/18511111111/count/ HTTP/1.1" 200 34
INFO 2019-07-04 18:32:20,127 basehttp 124 "GET /usernames/python1/count/ HTTP/1.1" 200 32
INFO 2019-07-04 18:32:20,231 basehttp 124 "POST /users/ HTTP/1.1" 201 52
ERROR 2019-07-05 10:04:50,693 exceptions 26 [<verifications.views.ImageCodeView object at 0x7f7f0dd29ba8>] Error 111 connecting to 127.0.0.1:6379. Connection refused.
ERROR 2019-07-05 10:04:50,705 basehttp 124 "GET /image_codes/7f8e6165-f70a-41fc-8c2b-49d53edbf101/ HTTP/1.1" 507 35
INFO 2019-07-05 10:05:15,748 basehttp 124 "GET /image_codes/46344f54-2c40-453f-9294-1bec992e5015/ HTTP/1.1" 200 3166
INFO 2019-07-05 10:06:09,216 basehttp 124 "GET /mobiles/18522222222/count/ HTTP/1.1" 200 34
INFO 2019-07-05 10:06:23,775 basehttp 124 "GET /usernames/python1/count/ HTTP/1.1" 200 32
INFO 2019-07-05 10:06:28,227 basehttp 124 "GET /usernames/python/count/ HTTP/1.1" 200 31
INFO 2019-07-05 10:06:31,045 basehttp 124 "GET /usernames/python2/count/ HTTP/1.1" 200 32
INFO 2019-07-05 10:06:40,064 basehttp 124 "GET /mobiles/18522222222/count/ HTTP/1.1" 200 34
INFO 2019-07-05 10:06:40,298 basehttp 124 "GET /sms_codes/18522222222/?text=GYVR&image_code_id=46344f54-2c40-453f-9294-1bec992e5015 HTTP/1.1" 200 16
INFO 2019-07-05 10:06:54,329 basehttp 124 "GET /mobiles/18533333333/count/ HTTP/1.1" 200 34
ERROR 2019-07-05 10:07:34,263 exception 135 Internal Server Error: /users/
Traceback (most recent call last):
  File "/home/python/.virtualenvs/gangquan_12/lib/python3.5/site-packages/django/core/handlers/exception.py", line 41, in inner
    response = get_response(request)
  File "/home/python/.virtualenvs/gangquan_12/lib/python3.5/site-packages/django/core/handlers/base.py", line 187, in _get_response
    response = self.process_exception_by_middleware(e, request)
  File "/home/python/.virtualenvs/gangquan_12/lib/python3.5/site-packages/django/core/handlers/base.py", line 185, in _get_response
    response = wrapped_callback(request, *callback_args, **callback_kwargs)
  File "/home/python/.virtualenvs/gangquan_12/lib/python3.5/site-packages/django/views/decorators/csrf.py", line 58, in wrapped_view
    return view_func(*args, **kwargs)
  File "/home/python/.virtualenvs/gangquan_12/lib/python3.5/site-packages/django/views/generic/base.py", line 68, in view
    return self.dispatch(request, *args, **kwargs)
  File "/home/python/.virtualenvs/gangquan_12/lib/python3.5/site-packages/rest_framework/views.py", line 495, in dispatch
    response = self.handle_exception(exc)
  File "/home/python/.virtualenvs/gangquan_12/lib/python3.5/site-packages/rest_framework/views.py", line 455, in handle_exception
    self.raise_uncaught_exception(exc)
  File "/home/python/.virtualenvs/gangquan_12/lib/python3.5/site-packages/rest_framework/views.py", line 492, in dispatch
    response = handler(request, *args, **kwargs)
  File "/home/python/.virtualenvs/gangquan_12/lib/python3.5/site-packages/rest_framework/generics.py", line 192, in post
    return self.create(request, *args, **kwargs)
  File "/home/python/.virtualenvs/gangquan_12/lib/python3.5/site-packages/rest_framework/mixins.py", line 20, in create
    serializer.is_valid(raise_exception=True)
  File "/home/python/.virtualenvs/gangquan_12/lib/python3.5/site-packages/rest_framework/serializers.py", line 236, in is_valid
    self._validated_data = self.run_validation(self.initial_data)
  File "/home/python/.virtualenvs/gangquan_12/lib/python3.5/site-packages/rest_framework/serializers.py", line 434, in run_validation
    value = self.to_internal_value(data)
  File "/home/python/.virtualenvs/gangquan_12/lib/python3.5/site-packages/rest_framework/serializers.py", line 485, in to_internal_value
    fields = self._writable_fields
  File "/home/python/.virtualenvs/gangquan_12/lib/python3.5/site-packages/django/utils/functional.py", line 35, in __get__
    res = instance.__dict__[self.name] = self.func(instance)
  File "/home/python/.virtualenvs/gangquan_12/lib/python3.5/site-packages/rest_framework/serializers.py", line 370, in _writable_fields
    field for field in self.fields.values() if not field.read_only
  File "/home/python/.virtualenvs/gangquan_12/lib/python3.5/site-packages/rest_framework/serializers.py", line 363, in fields
    for key, value in self.get_fields().items():
  File "/home/python/.virtualenvs/gangquan_12/lib/python3.5/site-packages/rest_framework/serializers.py", line 1025, in get_fields
    field_names = self.get_field_names(declared_fields, info)
  File "/home/python/.virtualenvs/gangquan_12/lib/python3.5/site-packages/rest_framework/serializers.py", line 1126, in get_field_names
    serializer_class=self.__class__.__name__
AssertionError: The field 'token' was declared on serializer CreateUserSerializer, but has not been included in the 'fields' option.
INFO 2019-07-05 10:07:34,267 basehttp 124 "GET /usernames/python2/count/ HTTP/1.1" 200 32
INFO 2019-07-05 10:07:34,268 basehttp 124 "OPTIONS /users/ HTTP/1.1" 200 0
INFO 2019-07-05 10:07:34,274 basehttp 124 "GET /mobiles/18533333333/count/ HTTP/1.1" 200 34
ERROR 2019-07-05 10:07:34,388 basehttp 124 "POST /users/ HTTP/1.1" 500 20005
INFO 2019-07-05 10:07:40,980 basehttp 124 "GET /image_codes/656a4010-36a4-431e-891a-758363a54580/ HTTP/1.1" 200 3080
INFO 2019-07-05 10:07:45,114 basehttp 124 "GET /usernames/python2/count/ HTTP/1.1" 200 32
INFO 2019-07-05 10:07:54,083 basehttp 124 "GET /mobiles/18533333333/count/ HTTP/1.1" 200 34
INFO 2019-07-05 10:10:26,284 basehttp 124 "GET /sms_codes/18533333333/?text=OFL9&image_code_id=656a4010-36a4-431e-891a-758363a54580 HTTP/1.1" 200 16
INFO 2019-07-05 10:10:26,287 basehttp 124 "GET /mobiles/18533333333/count/ HTTP/1.1" 200 34
INFO 2019-07-05 10:11:08,472 basehttp 124 "GET /usernames/python2/count/ HTTP/1.1" 200 32
ERROR 2019-07-05 10:11:08,484 exception 135 Internal Server Error: /users/
Traceback (most recent call last):
  File "/home/python/.virtualenvs/gangquan_12/lib/python3.5/site-packages/django/core/handlers/exception.py", line 41, in inner
    response = get_response(request)
  File "/home/python/.virtualenvs/gangquan_12/lib/python3.5/site-packages/django/core/handlers/base.py", line 187, in _get_response
    response = self.process_exception_by_middleware(e, request)
  File "/home/python/.virtualenvs/gangquan_12/lib/python3.5/site-packages/django/core/handlers/base.py", line 185, in _get_response
    response = wrapped_callback(request, *callback_args, **callback_kwargs)
  File "/home/python/.virtualenvs/gangquan_12/lib/python3.5/site-packages/django/views/decorators/csrf.py", line 58, in wrapped_view
    return view_func(*args, **kwargs)
  File "/home/python/.virtualenvs/gangquan_12/lib/python3.5/site-packages/django/views/generic/base.py", line 68, in view
    return self.dispatch(request, *args, **kwargs)
  File "/home/python/.virtualenvs/gangquan_12/lib/python3.5/site-packages/rest_framework/views.py", line 495, in dispatch
    response = self.handle_exception(exc)
  File "/home/python/.virtualenvs/gangquan_12/lib/python3.5/site-packages/rest_framework/views.py", line 455, in handle_exception
    self.raise_uncaught_exception(exc)
  File "/home/python/.virtualenvs/gangquan_12/lib/python3.5/site-packages/rest_framework/views.py", line 492, in dispatch
    response = handler(request, *args, **kwargs)
  File "/home/python/.virtualenvs/gangquan_12/lib/python3.5/site-packages/rest_framework/generics.py", line 192, in post
    return self.create(request, *args, **kwargs)
  File "/home/python/.virtualenvs/gangquan_12/lib/python3.5/site-packages/rest_framework/mixins.py", line 20, in create
    serializer.is_valid(raise_exception=True)
  File "/home/python/.virtualenvs/gangquan_12/lib/python3.5/site-packages/rest_framework/serializers.py", line 236, in is_valid
    self._validated_data = self.run_validation(self.initial_data)
  File "/home/python/.virtualenvs/gangquan_12/lib/python3.5/site-packages/rest_framework/serializers.py", line 434, in run_validation
    value = self.to_internal_value(data)
  File "/home/python/.virtualenvs/gangquan_12/lib/python3.5/site-packages/rest_framework/serializers.py", line 485, in to_internal_value
    fields = self._writable_fields
  File "/home/python/.virtualenvs/gangquan_12/lib/python3.5/site-packages/django/utils/functional.py", line 35, in __get__
    res = instance.__dict__[self.name] = self.func(instance)
  File "/home/python/.virtualenvs/gangquan_12/lib/python3.5/site-packages/rest_framework/serializers.py", line 370, in _writable_fields
    field for field in self.fields.values() if not field.read_only
  File "/home/python/.virtualenvs/gangquan_12/lib/python3.5/site-packages/rest_framework/serializers.py", line 363, in fields
    for key, value in self.get_fields().items():
  File "/home/python/.virtualenvs/gangquan_12/lib/python3.5/site-packages/rest_framework/serializers.py", line 1025, in get_fields
    field_names = self.get_field_names(declared_fields, info)
  File "/home/python/.virtualenvs/gangquan_12/lib/python3.5/site-packages/rest_framework/serializers.py", line 1126, in get_field_names
    serializer_class=self.__class__.__name__
AssertionError: The field 'token' was declared on serializer CreateUserSerializer, but has not been included in the 'fields' option.
INFO 2019-07-05 10:11:08,506 basehttp 124 "GET /mobiles/18533333333/count/ HTTP/1.1" 200 34
ERROR 2019-07-05 10:11:08,519 basehttp 124 "POST /users/ HTTP/1.1" 500 20004
INFO 2019-07-05 10:27:35,336 basehttp 124 "GET /image_codes/6136a3d9-b7af-4211-9dc7-3ba436a58273/ HTTP/1.1" 200 3271
INFO 2019-07-05 10:27:42,289 basehttp 124 "GET /usernames/python2/count/ HTTP/1.1" 200 32
INFO 2019-07-05 10:27:52,800 basehttp 124 "GET /mobiles/18533333333/count/ HTTP/1.1" 200 34
INFO 2019-07-05 10:27:59,782 basehttp 124 "GET /mobiles/18533333333/count/ HTTP/1.1" 200 34
INFO 2019-07-05 10:27:59,833 basehttp 124 "GET /sms_codes/18533333333/?text=Z5DY&image_code_id=6136a3d9-b7af-4211-9dc7-3ba436a58273 HTTP/1.1" 200 16
INFO 2019-07-05 10:28:17,108 basehttp 124 "OPTIONS /users/ HTTP/1.1" 200 0
INFO 2019-07-05 10:28:17,109 basehttp 124 "GET /mobiles/18533333333/count/ HTTP/1.1" 200 34
INFO 2019-07-05 10:28:17,121 basehttp 124 "GET /usernames/python2/count/ HTTP/1.1" 200 32
INFO 2019-07-05 10:28:17,321 basehttp 124 "POST /users/ HTTP/1.1" 201 227
INFO 2019-07-05 10:29:53,518 basehttp 124 "GET /image_codes/7dd1b83f-5eef-4370-8a15-5e623064d796/ HTTP/1.1" 200 3142
INFO 2019-07-05 10:30:20,269 basehttp 124 "GET /usernames/python1/count/ HTTP/1.1" 200 32
INFO 2019-07-05 10:30:32,719 basehttp 124 "GET /mobiles/18533333333/count/ HTTP/1.1" 200 34
INFO 2019-07-05 10:30:41,456 basehttp 124 "GET /sms_codes/18533333333/?text=CKVI&image_code_id=7dd1b83f-5eef-4370-8a15-5e623064d796 HTTP/1.1" 200 16
INFO 2019-07-05 10:30:41,462 basehttp 124 "GET /mobiles/18533333333/count/ HTTP/1.1" 200 34
INFO 2019-07-05 10:30:50,519 basehttp 124 "GET /mobiles/18533333333/count/ HTTP/1.1" 200 34
INFO 2019-07-05 10:30:50,524 basehttp 124 "GET /usernames/python1/count/ HTTP/1.1" 200 32
INFO 2019-07-05 10:30:50,623 basehttp 124 "POST /users/ HTTP/1.1" 201 227
WARNING 2019-07-05 10:31:04,887 basehttp 124 "GET /users/ HTTP/1.1" 405 8815
INFO 2019-07-05 10:31:04,938 basehttp 124 "GET /static/rest_framework/css/default.css HTTP/1.1" 200 1131
INFO 2019-07-05 10:31:04,939 basehttp 124 "GET /static/rest_framework/css/bootstrap-tweaks.css HTTP/1.1" 200 3385
INFO 2019-07-05 10:31:04,972 basehttp 124 "GET /static/rest_framework/css/prettify.css HTTP/1.1" 200 817
INFO 2019-07-05 10:31:04,997 basehttp 124 "GET /static/rest_framework/js/bootstrap.min.js HTTP/1.1" 200 37608
INFO 2019-07-05 10:31:04,999 basehttp 124 "GET /static/rest_framework/js/ajax-form.js HTTP/1.1" 200 3597
INFO 2019-07-05 10:31:05,000 basehttp 124 "GET /static/rest_framework/js/jquery-3.3.1.min.js HTTP/1.1" 200 86927
INFO 2019-07-05 10:31:05,006 basehttp 124 "GET /static/rest_framework/js/csrf.js HTTP/1.1" 200 1719
INFO 2019-07-05 10:31:05,016 basehttp 124 "GET /static/rest_framework/css/bootstrap.min.css HTTP/1.1" 200 121457
INFO 2019-07-05 10:31:05,022 basehttp 124 "GET /static/rest_framework/js/prettify-min.js HTTP/1.1" 200 13632
INFO 2019-07-05 10:31:05,023 basehttp 124 "GET /static/rest_framework/js/default.js HTTP/1.1" 200 1268
INFO 2019-07-05 10:31:05,301 basehttp 124 "GET /static/rest_framework/img/grid.png HTTP/1.1" 200 1458
WARNING 2019-07-05 10:31:05,596 base 152 Not Found: /favicon.ico
WARNING 2019-07-05 10:31:05,596 basehttp 124 "GET /favicon.ico HTTP/1.1" 404 2897
INFO 2019-07-05 11:36:10,012 basehttp 124 "OPTIONS /authorizations/ HTTP/1.1" 200 0
INFO 2019-07-05 11:36:10,063 basehttp 124 "POST /authorizations/ HTTP/1.1" 200 175
