INFO 2019-07-01 11:27:27,387 basehttp 124 "GET /image_codes/11 HTTP/1.1" 301 0
INFO 2019-07-01 11:27:29,877 basehttp 124 "GET /image_codes/11 HTTP/1.1" 301 0
ERROR 2019-07-01 11:27:48,414 exception 135 Internal Server Error: /image_codes/11/
Traceback (most recent call last):
  File "/home/python/.virtualenvs/gangquan_12/lib/python3.5/site-packages/redis/connection.py", line 492, in connect
    sock = self._connect()
  File "/home/python/.virtualenvs/gangquan_12/lib/python3.5/site-packages/redis/connection.py", line 550, in _connect
    raise err
  File "/home/python/.virtualenvs/gangquan_12/lib/python3.5/site-packages/redis/connection.py", line 538, in _connect
    sock.connect(socket_address)
ConnectionRefusedError: [Errno 111] Connection refused

During handling of the above exception, another exception occurred:

Traceback (most recent call last):
  File "/home/python/.virtualenvs/gangquan_12/lib/python3.5/site-packages/rest_framework/views.py", line 492, in dispatch
    response = handler(request, *args, **kwargs)
  File "/home/python/Desktop/gangquanwang/gangquan_12/gangquan_12/apps/verifications/views.py", line 22, in get
    redis_conn.setex('img_%s' % image_code_id, constants.IMAGE_CODE_REDIS_EXPIRES , text)
  File "/home/python/.virtualenvs/gangquan_12/lib/python3.5/site-packages/redis/client.py", line 1472, in setex
    return self.execute_command('SETEX', name, time, value)
  File "/home/python/.virtualenvs/gangquan_12/lib/python3.5/site-packages/redis/client.py", line 772, in execute_command
    connection = pool.get_connection(command_name, **options)
  File "/home/python/.virtualenvs/gangquan_12/lib/python3.5/site-packages/redis/connection.py", line 994, in get_connection
    connection.connect()
  File "/home/python/.virtualenvs/gangquan_12/lib/python3.5/site-packages/redis/connection.py", line 497, in connect
    raise ConnectionError(self._error_message(e))
redis.exceptions.ConnectionError: Error 111 connecting to 10.211.55.5:6379. Connection refused.

During handling of the above exception, another exception occurred:

Traceback (most recent call last):
  File "/home/python/.virtualenvs/gangquan_12/lib/python3.5/site-packages/rest_framework/settings.py", line 183, in import_from_string
    module = import_module(module_path)
  File "/home/python/.virtualenvs/gangquan_12/lib/python3.5/importlib/__init__.py", line 126, in import_module
    return _bootstrap._gcd_import(name[level:], package, level)
  File "<frozen importlib._bootstrap>", line 986, in _gcd_import
  File "<frozen importlib._bootstrap>", line 969, in _find_and_load
  File "<frozen importlib._bootstrap>", line 956, in _find_and_load_unlocked
ImportError: No module named 'gangquan_12.utils.exceptions'

During handling of the above exception, another exception occurred:

Traceback (most recent call last):
  File "/home/python/.virtualenvs/gangquan_12/lib/python3.5/site-packages/django/core/handlers/exception.py", line 41, in inner
    response = get_response(request)
  File "/home/python/.virtualenvs/gangquan_12/lib/python3.5/site-packages/django/core/handlers/base.py", line 187, in _get_response
    response = self.process_exception_by_middleware(e, request)
  File "/home/python/.virtualenvs/gangquan_12/lib/python3.5/site-packages/django/core/handlers/base.py", line 185, in _get_response
    response = wrapped_callback(request, *callback_args, **callback_kwargs)
  File "/home/python/.virtualenvs/gangquan_12/lib/python3.5/site-packages/django/views/decorators/csrf.py", line 58, in wrapped_view
    return view_func(*args, **kwargs)
  File "/home/python/.virtualenvs/gangquan_12/lib/python3.5/site-packages/django/views/generic/base.py", line 68, in view
    return self.dispatch(request, *args, **kwargs)
  File "/home/python/.virtualenvs/gangquan_12/lib/python3.5/site-packages/rest_framework/views.py", line 495, in dispatch
    response = self.handle_exception(exc)
  File "/home/python/.virtualenvs/gangquan_12/lib/python3.5/site-packages/rest_framework/views.py", line 449, in handle_exception
    exception_handler = self.get_exception_handler()
  File "/home/python/.virtualenvs/gangquan_12/lib/python3.5/site-packages/rest_framework/views.py", line 300, in get_exception_handler
    return self.settings.EXCEPTION_HANDLER
  File "/home/python/.virtualenvs/gangquan_12/lib/python3.5/site-packages/rest_framework/settings.py", line 227, in __getattr__
    val = perform_import(val, attr)
  File "/home/python/.virtualenvs/gangquan_12/lib/python3.5/site-packages/rest_framework/settings.py", line 170, in perform_import
    return import_from_string(val, setting_name)
  File "/home/python/.virtualenvs/gangquan_12/lib/python3.5/site-packages/rest_framework/settings.py", line 187, in import_from_string
    raise ImportError(msg)
ImportError: Could not import 'gangquan_12.utils.exceptions.exception_handler' for API setting 'EXCEPTION_HANDLER'. ImportError: No module named 'gangquan_12.utils.exceptions'.
ERROR 2019-07-01 11:27:48,611 basehttp 124 "GET /image_codes/11/ HTTP/1.1" 500 158427
ERROR 2019-07-01 11:27:50,890 exception 135 Internal Server Error: /image_codes/11/
Traceback (most recent call last):
  File "/home/python/.virtualenvs/gangquan_12/lib/python3.5/site-packages/redis/connection.py", line 492, in connect
    sock = self._connect()
  File "/home/python/.virtualenvs/gangquan_12/lib/python3.5/site-packages/redis/connection.py", line 550, in _connect
    raise err
  File "/home/python/.virtualenvs/gangquan_12/lib/python3.5/site-packages/redis/connection.py", line 538, in _connect
    sock.connect(socket_address)
ConnectionRefusedError: [Errno 111] Connection refused

During handling of the above exception, another exception occurred:

Traceback (most recent call last):
  File "/home/python/.virtualenvs/gangquan_12/lib/python3.5/site-packages/rest_framework/views.py", line 492, in dispatch
    response = handler(request, *args, **kwargs)
  File "/home/python/Desktop/gangquanwang/gangquan_12/gangquan_12/apps/verifications/views.py", line 22, in get
    redis_conn.setex('img_%s' % image_code_id, constants.IMAGE_CODE_REDIS_EXPIRES , text)
  File "/home/python/.virtualenvs/gangquan_12/lib/python3.5/site-packages/redis/client.py", line 1472, in setex
    return self.execute_command('SETEX', name, time, value)
  File "/home/python/.virtualenvs/gangquan_12/lib/python3.5/site-packages/redis/client.py", line 772, in execute_command
    connection = pool.get_connection(command_name, **options)
  File "/home/python/.virtualenvs/gangquan_12/lib/python3.5/site-packages/redis/connection.py", line 994, in get_connection
    connection.connect()
  File "/home/python/.virtualenvs/gangquan_12/lib/python3.5/site-packages/redis/connection.py", line 497, in connect
    raise ConnectionError(self._error_message(e))
redis.exceptions.ConnectionError: Error 111 connecting to 10.211.55.5:6379. Connection refused.

During handling of the above exception, another exception occurred:

Traceback (most recent call last):
  File "/home/python/.virtualenvs/gangquan_12/lib/python3.5/site-packages/rest_framework/settings.py", line 183, in import_from_string
    module = import_module(module_path)
  File "/home/python/.virtualenvs/gangquan_12/lib/python3.5/importlib/__init__.py", line 126, in import_module
    return _bootstrap._gcd_import(name[level:], package, level)
  File "<frozen importlib._bootstrap>", line 986, in _gcd_import
  File "<frozen importlib._bootstrap>", line 969, in _find_and_load
  File "<frozen importlib._bootstrap>", line 956, in _find_and_load_unlocked
ImportError: No module named 'gangquan_12.utils.exceptions'

During handling of the above exception, another exception occurred:

Traceback (most recent call last):
  File "/home/python/.virtualenvs/gangquan_12/lib/python3.5/site-packages/django/core/handlers/exception.py", line 41, in inner
    response = get_response(request)
  File "/home/python/.virtualenvs/gangquan_12/lib/python3.5/site-packages/django/core/handlers/base.py", line 187, in _get_response
    response = self.process_exception_by_middleware(e, request)
  File "/home/python/.virtualenvs/gangquan_12/lib/python3.5/site-packages/django/core/handlers/base.py", line 185, in _get_response
    response = wrapped_callback(request, *callback_args, **callback_kwargs)
  File "/home/python/.virtualenvs/gangquan_12/lib/python3.5/site-packages/django/views/decorators/csrf.py", line 58, in wrapped_view
    return view_func(*args, **kwargs)
  File "/home/python/.virtualenvs/gangquan_12/lib/python3.5/site-packages/django/views/generic/base.py", line 68, in view
    return self.dispatch(request, *args, **kwargs)
  File "/home/python/.virtualenvs/gangquan_12/lib/python3.5/site-packages/rest_framework/views.py", line 495, in dispatch
    response = self.handle_exception(exc)
  File "/home/python/.virtualenvs/gangquan_12/lib/python3.5/site-packages/rest_framework/views.py", line 449, in handle_exception
    exception_handler = self.get_exception_handler()
  File "/home/python/.virtualenvs/gangquan_12/lib/python3.5/site-packages/rest_framework/views.py", line 300, in get_exception_handler
    return self.settings.EXCEPTION_HANDLER
  File "/home/python/.virtualenvs/gangquan_12/lib/python3.5/site-packages/rest_framework/settings.py", line 227, in __getattr__
    val = perform_import(val, attr)
  File "/home/python/.virtualenvs/gangquan_12/lib/python3.5/site-packages/rest_framework/settings.py", line 170, in perform_import
    return import_from_string(val, setting_name)
  File "/home/python/.virtualenvs/gangquan_12/lib/python3.5/site-packages/rest_framework/settings.py", line 187, in import_from_string
    raise ImportError(msg)
ImportError: Could not import 'gangquan_12.utils.exceptions.exception_handler' for API setting 'EXCEPTION_HANDLER'. ImportError: No module named 'gangquan_12.utils.exceptions'.
ERROR 2019-07-01 11:27:50,997 basehttp 124 "GET /image_codes/11/ HTTP/1.1" 500 158557
WARNING 2019-07-01 11:27:51,326 base 152 Not Found: /favicon.ico
WARNING 2019-07-01 11:27:51,326 basehttp 124 "GET /favicon.ico HTTP/1.1" 404 2161
INFO 2019-07-01 11:29:04,081 basehttp 124 "GET /image_codes/11/ HTTP/1.1" 200 3191
INFO 2019-07-01 11:29:13,403 basehttp 124 "GET /image_codes/12/ HTTP/1.1" 200 3359
INFO 2019-07-01 11:29:21,412 basehttp 124 "GET /image_codes/13/ HTTP/1.1" 200 3323
INFO 2019-07-01 11:30:24,959 basehttp 124 "GET /image_codes/13/ HTTP/1.1" 200 2943
INFO 2019-07-01 11:30:29,416 basehttp 124 "GET /image_codes/13/ HTTP/1.1" 200 3426
WARNING 2019-07-01 11:34:41,782 base 152 Not Found: /
WARNING 2019-07-01 11:34:41,783 basehttp 124 "GET / HTTP/1.1" 404 2110
INFO 2019-07-01 11:34:53,578 basehttp 124 "GET /image_codes/11/ HTTP/1.1" 200 3029
INFO 2019-07-01 12:39:46,555 basehttp 124 "GET /image_codes/ab9eacc3-9e99-41eb-89d4-c2ebe2a1a8b9/ HTTP/1.1" 200 2847
INFO 2019-07-01 12:39:55,117 basehttp 124 "GET /image_codes/3cd17993-0807-444b-a2f2-b0212345fc6c/ HTTP/1.1" 200 2921
INFO 2019-07-01 12:39:55,405 basehttp 124 "GET /image_codes/e946a6b5-cac3-4259-b766-57b26458b6a0/ HTTP/1.1" 200 3110
INFO 2019-07-01 12:39:55,816 basehttp 124 "GET /image_codes/1f96cd37-9fa5-4b58-a2db-19aeacfc2b2d/ HTTP/1.1" 200 3186
INFO 2019-07-01 12:39:56,033 basehttp 124 "GET /image_codes/ec5d74c4-6309-48c3-a429-70d101c67b55/ HTTP/1.1" 200 3219
INFO 2019-07-01 12:39:56,200 basehttp 124 "GET /image_codes/1c1b4fd0-17ef-4949-aad5-85b400d0cb05/ HTTP/1.1" 200 2899
INFO 2019-07-01 12:39:56,381 basehttp 124 "GET /image_codes/b0be4ba3-0c6b-4a14-9ba2-1a610fca47d9/ HTTP/1.1" 200 2652
