INFO 2019-07-01 11:27:27,387 basehttp 124 "GET /image_codes/11 HTTP/1.1" 301 0
INFO 2019-07-01 11:27:29,877 basehttp 124 "GET /image_codes/11 HTTP/1.1" 301 0
ERROR 2019-07-01 11:27:48,414 exception 135 Internal Server Error: /image_codes/11/
Traceback (most recent call last):
  File "/home/python/.virtualenvs/gangquan_12/lib/python3.5/site-packages/redis/connection.py", line 492, in connect
    sock = self._connect()
  File "/home/python/.virtualenvs/gangquan_12/lib/python3.5/site-packages/redis/connection.py", line 550, in _connect
    raise err
  File "/home/python/.virtualenvs/gangquan_12/lib/python3.5/site-packages/redis/connection.py", line 538, in _connect
    sock.connect(socket_address)
ConnectionRefusedError: [Errno 111] Connection refused

During handling of the above exception, another exception occurred:

Traceback (most recent call last):
  File "/home/python/.virtualenvs/gangquan_12/lib/python3.5/site-packages/rest_framework/views.py", line 492, in dispatch
    response = handler(request, *args, **kwargs)
  File "/home/python/Desktop/gangquanwang/gangquan_12/gangquan_12/apps/verifications/views.py", line 22, in get
    redis_conn.setex('img_%s' % image_code_id, constants.IMAGE_CODE_REDIS_EXPIRES , text)
  File "/home/python/.virtualenvs/gangquan_12/lib/python3.5/site-packages/redis/client.py", line 1472, in setex
    return self.execute_command('SETEX', name, time, value)
  File "/home/python/.virtualenvs/gangquan_12/lib/python3.5/site-packages/redis/client.py", line 772, in execute_command
    connection = pool.get_connection(command_name, **options)
  File "/home/python/.virtualenvs/gangquan_12/lib/python3.5/site-packages/redis/connection.py", line 994, in get_connection
    connection.connect()
  File "/home/python/.virtualenvs/gangquan_12/lib/python3.5/site-packages/redis/connection.py", line 497, in connect
    raise ConnectionError(self._error_message(e))
redis.exceptions.ConnectionError: Error 111 connecting to 10.211.55.5:6379. Connection refused.

During handling of the above exception, another exception occurred:

Traceback (most recent call last):
  File "/home/python/.virtualenvs/gangquan_12/lib/python3.5/site-packages/rest_framework/settings.py", line 183, in import_from_string
    module = import_module(module_path)
  File "/home/python/.virtualenvs/gangquan_12/lib/python3.5/importlib/__init__.py", line 126, in import_module
    return _bootstrap._gcd_import(name[level:], package, level)
  File "<frozen importlib._bootstrap>", line 986, in _gcd_import
  File "<frozen importlib._bootstrap>", line 969, in _find_and_load
  File "<frozen importlib._bootstrap>", line 956, in _find_and_load_unlocked
ImportError: No module named 'gangquan_12.utils.exceptions'

During handling of the above exception, another exception occurred:

Traceback (most recent call last):
  File "/home/python/.virtualenvs/gangquan_12/lib/python3.5/site-packages/django/core/handlers/exception.py", line 41, in inner
    response = get_response(request)
  File "/home/python/.virtualenvs/gangquan_12/lib/python3.5/site-packages/django/core/handlers/base.py", line 187, in _get_response
    response = self.process_exception_by_middleware(e, request)
  File "/home/python/.virtualenvs/gangquan_12/lib/python3.5/site-packages/django/core/handlers/base.py", line 185, in _get_response
    response = wrapped_callback(request, *callback_args, **callback_kwargs)
  File "/home/python/.virtualenvs/gangquan_12/lib/python3.5/site-packages/django/views/decorators/csrf.py", line 58, in wrapped_view
    return view_func(*args, **kwargs)
  File "/home/python/.virtualenvs/gangquan_12/lib/python3.5/site-packages/django/views/generic/base.py", line 68, in view
    return self.dispatch(request, *args, **kwargs)
  File "/home/python/.virtualenvs/gangquan_12/lib/python3.5/site-packages/rest_framework/views.py", line 495, in dispatch
    response = self.handle_exception(exc)
  File "/home/python/.virtualenvs/gangquan_12/lib/python3.5/site-packages/rest_framework/views.py", line 449, in handle_exception
    exception_handler = self.get_exception_handler()
  File "/home/python/.virtualenvs/gangquan_12/lib/python3.5/site-packages/rest_framework/views.py", line 300, in get_exception_handler
    return self.settings.EXCEPTION_HANDLER
  File "/home/python/.virtualenvs/gangquan_12/lib/python3.5/site-packages/rest_framework/settings.py", line 227, in __getattr__
    val = perform_import(val, attr)
  File "/home/python/.virtualenvs/gangquan_12/lib/python3.5/site-packages/rest_framework/settings.py", line 170, in perform_import
    return import_from_string(val, setting_name)
  File "/home/python/.virtualenvs/gangquan_12/lib/python3.5/site-packages/rest_framework/settings.py", line 187, in import_from_string
    raise ImportError(msg)
ImportError: Could not import 'gangquan_12.utils.exceptions.exception_handler' for API setting 'EXCEPTION_HANDLER'. ImportError: No module named 'gangquan_12.utils.exceptions'.
ERROR 2019-07-01 11:27:48,611 basehttp 124 "GET /image_codes/11/ HTTP/1.1" 500 158427
ERROR 2019-07-01 11:27:50,890 exception 135 Internal Server Error: /image_codes/11/
Traceback (most recent call last):
  File "/home/python/.virtualenvs/gangquan_12/lib/python3.5/site-packages/redis/connection.py", line 492, in connect
    sock = self._connect()
  File "/home/python/.virtualenvs/gangquan_12/lib/python3.5/site-packages/redis/connection.py", line 550, in _connect
    raise err
  File "/home/python/.virtualenvs/gangquan_12/lib/python3.5/site-packages/redis/connection.py", line 538, in _connect
    sock.connect(socket_address)
ConnectionRefusedError: [Errno 111] Connection refused

During handling of the above exception, another exception occurred:

Traceback (most recent call last):
  File "/home/python/.virtualenvs/gangquan_12/lib/python3.5/site-packages/rest_framework/views.py", line 492, in dispatch
    response = handler(request, *args, **kwargs)
  File "/home/python/Desktop/gangquanwang/gangquan_12/gangquan_12/apps/verifications/views.py", line 22, in get
    redis_conn.setex('img_%s' % image_code_id, constants.IMAGE_CODE_REDIS_EXPIRES , text)
  File "/home/python/.virtualenvs/gangquan_12/lib/python3.5/site-packages/redis/client.py", line 1472, in setex
    return self.execute_command('SETEX', name, time, value)
  File "/home/python/.virtualenvs/gangquan_12/lib/python3.5/site-packages/redis/client.py", line 772, in execute_command
    connection = pool.get_connection(command_name, **options)
  File "/home/python/.virtualenvs/gangquan_12/lib/python3.5/site-packages/redis/connection.py", line 994, in get_connection
    connection.connect()
  File "/home/python/.virtualenvs/gangquan_12/lib/python3.5/site-packages/redis/connection.py", line 497, in connect
    raise ConnectionError(self._error_message(e))
redis.exceptions.ConnectionError: Error 111 connecting to 10.211.55.5:6379. Connection refused.

During handling of the above exception, another exception occurred:

Traceback (most recent call last):
  File "/home/python/.virtualenvs/gangquan_12/lib/python3.5/site-packages/rest_framework/settings.py", line 183, in import_from_string
    module = import_module(module_path)
  File "/home/python/.virtualenvs/gangquan_12/lib/python3.5/importlib/__init__.py", line 126, in import_module
    return _bootstrap._gcd_import(name[level:], package, level)
  File "<frozen importlib._bootstrap>", line 986, in _gcd_import
  File "<frozen importlib._bootstrap>", line 969, in _find_and_load
  File "<frozen importlib._bootstrap>", line 956, in _find_and_load_unlocked
ImportError: No module named 'gangquan_12.utils.exceptions'

During handling of the above exception, another exception occurred:

Traceback (most recent call last):
  File "/home/python/.virtualenvs/gangquan_12/lib/python3.5/site-packages/django/core/handlers/exception.py", line 41, in inner
    response = get_response(request)
  File "/home/python/.virtualenvs/gangquan_12/lib/python3.5/site-packages/django/core/handlers/base.py", line 187, in _get_response
    response = self.process_exception_by_middleware(e, request)
  File "/home/python/.virtualenvs/gangquan_12/lib/python3.5/site-packages/django/core/handlers/base.py", line 185, in _get_response
    response = wrapped_callback(request, *callback_args, **callback_kwargs)
  File "/home/python/.virtualenvs/gangquan_12/lib/python3.5/site-packages/django/views/decorators/csrf.py", line 58, in wrapped_view
    return view_func(*args, **kwargs)
  File "/home/python/.virtualenvs/gangquan_12/lib/python3.5/site-packages/django/views/generic/base.py", line 68, in view
    return self.dispatch(request, *args, **kwargs)
  File "/home/python/.virtualenvs/gangquan_12/lib/python3.5/site-packages/rest_framework/views.py", line 495, in dispatch
    response = self.handle_exception(exc)
  File "/home/python/.virtualenvs/gangquan_12/lib/python3.5/site-packages/rest_framework/views.py", line 449, in handle_exception
    exception_handler = self.get_exception_handler()
  File "/home/python/.virtualenvs/gangquan_12/lib/python3.5/site-packages/rest_framework/views.py", line 300, in get_exception_handler
    return self.settings.EXCEPTION_HANDLER
  File "/home/python/.virtualenvs/gangquan_12/lib/python3.5/site-packages/rest_framework/settings.py", line 227, in __getattr__
    val = perform_import(val, attr)
  File "/home/python/.virtualenvs/gangquan_12/lib/python3.5/site-packages/rest_framework/settings.py", line 170, in perform_import
    return import_from_string(val, setting_name)
  File "/home/python/.virtualenvs/gangquan_12/lib/python3.5/site-packages/rest_framework/settings.py", line 187, in import_from_string
    raise ImportError(msg)
ImportError: Could not import 'gangquan_12.utils.exceptions.exception_handler' for API setting 'EXCEPTION_HANDLER'. ImportError: No module named 'gangquan_12.utils.exceptions'.
ERROR 2019-07-01 11:27:50,997 basehttp 124 "GET /image_codes/11/ HTTP/1.1" 500 158557
WARNING 2019-07-01 11:27:51,326 base 152 Not Found: /favicon.ico
WARNING 2019-07-01 11:27:51,326 basehttp 124 "GET /favicon.ico HTTP/1.1" 404 2161
INFO 2019-07-01 11:29:04,081 basehttp 124 "GET /image_codes/11/ HTTP/1.1" 200 3191
INFO 2019-07-01 11:29:13,403 basehttp 124 "GET /image_codes/12/ HTTP/1.1" 200 3359
INFO 2019-07-01 11:29:21,412 basehttp 124 "GET /image_codes/13/ HTTP/1.1" 200 3323
INFO 2019-07-01 11:30:24,959 basehttp 124 "GET /image_codes/13/ HTTP/1.1" 200 2943
INFO 2019-07-01 11:30:29,416 basehttp 124 "GET /image_codes/13/ HTTP/1.1" 200 3426
WARNING 2019-07-01 11:34:41,782 base 152 Not Found: /
WARNING 2019-07-01 11:34:41,783 basehttp 124 "GET / HTTP/1.1" 404 2110
INFO 2019-07-01 11:34:53,578 basehttp 124 "GET /image_codes/11/ HTTP/1.1" 200 3029
INFO 2019-07-01 12:39:46,555 basehttp 124 "GET /image_codes/ab9eacc3-9e99-41eb-89d4-c2ebe2a1a8b9/ HTTP/1.1" 200 2847
INFO 2019-07-01 12:39:55,117 basehttp 124 "GET /image_codes/3cd17993-0807-444b-a2f2-b0212345fc6c/ HTTP/1.1" 200 2921
INFO 2019-07-01 12:39:55,405 basehttp 124 "GET /image_codes/e946a6b5-cac3-4259-b766-57b26458b6a0/ HTTP/1.1" 200 3110
INFO 2019-07-01 12:39:55,816 basehttp 124 "GET /image_codes/1f96cd37-9fa5-4b58-a2db-19aeacfc2b2d/ HTTP/1.1" 200 3186
INFO 2019-07-01 12:39:56,033 basehttp 124 "GET /image_codes/ec5d74c4-6309-48c3-a429-70d101c67b55/ HTTP/1.1" 200 3219
INFO 2019-07-01 12:39:56,200 basehttp 124 "GET /image_codes/1c1b4fd0-17ef-4949-aad5-85b400d0cb05/ HTTP/1.1" 200 2899
INFO 2019-07-01 12:39:56,381 basehttp 124 "GET /image_codes/b0be4ba3-0c6b-4a14-9ba2-1a610fca47d9/ HTTP/1.1" 200 2652
WARNING 2019-07-01 17:32:32,977 base 152 Not Found: /sms_code/15290980528/
WARNING 2019-07-01 17:32:32,979 basehttp 124 "GET /sms_code/15290980528/?text=12345&bbb=3333 HTTP/1.1" 404 2407
WARNING 2019-07-01 18:01:28,061 base 152 Not Found: /sms_code/15290980528/
WARNING 2019-07-01 18:01:28,061 basehttp 124 "GET /sms_code/15290980528/?text=12345&bbb=3333 HTTP/1.1" 404 2407
WARNING 2019-07-01 18:03:54,047 base 152 Not Found: /sms_code/15290980528/
WARNING 2019-07-01 18:03:54,047 basehttp 124 "GET /sms_code/15290980528/?text=12345&bbb=3333 HTTP/1.1" 404 2401
WARNING 2019-07-01 18:05:13,531 base 152 Not Found: /sms_code/15290980528/
WARNING 2019-07-01 18:05:13,532 basehttp 124 "GET /sms_code/15290980528/?text=12345&bbb=3333 HTTP/1.1" 404 2401
WARNING 2019-07-01 18:06:01,975 base 152 Not Found: /sms_code/15290980528/
WARNING 2019-07-01 18:06:01,976 basehttp 124 "GET /sms_code/15290980528/?text=12345&bbb=3333 HTTP/1.1" 404 2400
ERROR 2019-07-01 18:08:06,972 exception 135 Internal Server Error: /sms_code/15290980528/
Traceback (most recent call last):
  File "/home/python/.virtualenvs/gangquan_12/lib/python3.5/site-packages/rest_framework/views.py", line 492, in dispatch
    response = handler(request, *args, **kwargs)
  File "/home/python/Desktop/gangquanwang/gangquan_12/gangquan_12/apps/verifications/views.py", line 47, in get
    serialzier.is_valid(raise_exception=True)
  File "/home/python/.virtualenvs/gangquan_12/lib/python3.5/site-packages/rest_framework/serializers.py", line 244, in is_valid
    raise ValidationError(self.errors)
rest_framework.exceptions.ValidationError: {'image_code_id': [ErrorDetail(string='该字段是必填项。', code='required')], 'text': [ErrorDetail(string='请确保这个字段不能超过 4 个字符。', code='max_length')]}

During handling of the above exception, another exception occurred:

Traceback (most recent call last):
  File "/home/python/.virtualenvs/gangquan_12/lib/python3.5/site-packages/rest_framework/settings.py", line 183, in import_from_string
    module = import_module(module_path)
  File "/home/python/.virtualenvs/gangquan_12/lib/python3.5/importlib/__init__.py", line 126, in import_module
    return _bootstrap._gcd_import(name[level:], package, level)
  File "<frozen importlib._bootstrap>", line 986, in _gcd_import
  File "<frozen importlib._bootstrap>", line 969, in _find_and_load
  File "<frozen importlib._bootstrap>", line 956, in _find_and_load_unlocked
ImportError: No module named 'gangquan_12.utils.exceptions'

During handling of the above exception, another exception occurred:

Traceback (most recent call last):
  File "/home/python/.virtualenvs/gangquan_12/lib/python3.5/site-packages/django/core/handlers/exception.py", line 41, in inner
    response = get_response(request)
  File "/home/python/.virtualenvs/gangquan_12/lib/python3.5/site-packages/django/core/handlers/base.py", line 187, in _get_response
    response = self.process_exception_by_middleware(e, request)
  File "/home/python/.virtualenvs/gangquan_12/lib/python3.5/site-packages/django/core/handlers/base.py", line 185, in _get_response
    response = wrapped_callback(request, *callback_args, **callback_kwargs)
  File "/home/python/.virtualenvs/gangquan_12/lib/python3.5/site-packages/django/views/decorators/csrf.py", line 58, in wrapped_view
    return view_func(*args, **kwargs)
  File "/home/python/.virtualenvs/gangquan_12/lib/python3.5/site-packages/django/views/generic/base.py", line 68, in view
    return self.dispatch(request, *args, **kwargs)
  File "/home/python/.virtualenvs/gangquan_12/lib/python3.5/site-packages/rest_framework/views.py", line 495, in dispatch
    response = self.handle_exception(exc)
  File "/home/python/.virtualenvs/gangquan_12/lib/python3.5/site-packages/rest_framework/views.py", line 449, in handle_exception
    exception_handler = self.get_exception_handler()
  File "/home/python/.virtualenvs/gangquan_12/lib/python3.5/site-packages/rest_framework/views.py", line 300, in get_exception_handler
    return self.settings.EXCEPTION_HANDLER
  File "/home/python/.virtualenvs/gangquan_12/lib/python3.5/site-packages/rest_framework/settings.py", line 227, in __getattr__
    val = perform_import(val, attr)
  File "/home/python/.virtualenvs/gangquan_12/lib/python3.5/site-packages/rest_framework/settings.py", line 170, in perform_import
    return import_from_string(val, setting_name)
  File "/home/python/.virtualenvs/gangquan_12/lib/python3.5/site-packages/rest_framework/settings.py", line 187, in import_from_string
    raise ImportError(msg)
ImportError: Could not import 'gangquan_12.utils.exceptions.exception_handler' for API setting 'EXCEPTION_HANDLER'. ImportError: No module named 'gangquan_12.utils.exceptions'.
ERROR 2019-07-01 18:08:07,180 basehttp 124 "GET /sms_code/15290980528/?text=12345&bbb=3333 HTTP/1.1" 500 126651
ERROR 2019-07-01 18:19:48,194 exception 135 Internal Server Error: /sms_code/15290980528/
Traceback (most recent call last):
  File "/home/python/.virtualenvs/gangquan_12/lib/python3.5/site-packages/rest_framework/views.py", line 492, in dispatch
    response = handler(request, *args, **kwargs)
  File "/home/python/Desktop/gangquanwang/gangquan_12/gangquan_12/apps/verifications/views.py", line 47, in get
    serialzier.is_valid(raise_exception=True)
  File "/home/python/.virtualenvs/gangquan_12/lib/python3.5/site-packages/rest_framework/serializers.py", line 244, in is_valid
    raise ValidationError(self.errors)
rest_framework.exceptions.ValidationError: {'image_code_id': [ErrorDetail(string='该字段是必填项。', code='required')], 'text': [ErrorDetail(string='请确保这个字段不能超过 4 个字符。', code='max_length')]}

During handling of the above exception, another exception occurred:

Traceback (most recent call last):
  File "/home/python/.virtualenvs/gangquan_12/lib/python3.5/site-packages/rest_framework/settings.py", line 183, in import_from_string
    module = import_module(module_path)
  File "/home/python/.virtualenvs/gangquan_12/lib/python3.5/importlib/__init__.py", line 126, in import_module
    return _bootstrap._gcd_import(name[level:], package, level)
  File "<frozen importlib._bootstrap>", line 986, in _gcd_import
  File "<frozen importlib._bootstrap>", line 969, in _find_and_load
  File "<frozen importlib._bootstrap>", line 956, in _find_and_load_unlocked
ImportError: No module named 'gangquan_12.utils.exceptions'

During handling of the above exception, another exception occurred:

Traceback (most recent call last):
  File "/home/python/.virtualenvs/gangquan_12/lib/python3.5/site-packages/django/core/handlers/exception.py", line 41, in inner
    response = get_response(request)
  File "/home/python/.virtualenvs/gangquan_12/lib/python3.5/site-packages/django/core/handlers/base.py", line 187, in _get_response
    response = self.process_exception_by_middleware(e, request)
  File "/home/python/.virtualenvs/gangquan_12/lib/python3.5/site-packages/django/core/handlers/base.py", line 185, in _get_response
    response = wrapped_callback(request, *callback_args, **callback_kwargs)
  File "/home/python/.virtualenvs/gangquan_12/lib/python3.5/site-packages/django/views/decorators/csrf.py", line 58, in wrapped_view
    return view_func(*args, **kwargs)
  File "/home/python/.virtualenvs/gangquan_12/lib/python3.5/site-packages/django/views/generic/base.py", line 68, in view
    return self.dispatch(request, *args, **kwargs)
  File "/home/python/.virtualenvs/gangquan_12/lib/python3.5/site-packages/rest_framework/views.py", line 495, in dispatch
    response = self.handle_exception(exc)
  File "/home/python/.virtualenvs/gangquan_12/lib/python3.5/site-packages/rest_framework/views.py", line 449, in handle_exception
    exception_handler = self.get_exception_handler()
  File "/home/python/.virtualenvs/gangquan_12/lib/python3.5/site-packages/rest_framework/views.py", line 300, in get_exception_handler
    return self.settings.EXCEPTION_HANDLER
  File "/home/python/.virtualenvs/gangquan_12/lib/python3.5/site-packages/rest_framework/settings.py", line 227, in __getattr__
    val = perform_import(val, attr)
  File "/home/python/.virtualenvs/gangquan_12/lib/python3.5/site-packages/rest_framework/settings.py", line 170, in perform_import
    return import_from_string(val, setting_name)
  File "/home/python/.virtualenvs/gangquan_12/lib/python3.5/site-packages/rest_framework/settings.py", line 187, in import_from_string
    raise ImportError(msg)
ImportError: Could not import 'gangquan_12.utils.exceptions.exception_handler' for API setting 'EXCEPTION_HANDLER'. ImportError: No module named 'gangquan_12.utils.exceptions'.
ERROR 2019-07-01 18:19:48,278 basehttp 124 "GET /sms_code/15290980528/?text=12345&bbb=3333 HTTP/1.1" 500 126651
ERROR 2019-07-01 18:21:40,703 exception 135 Internal Server Error: /sms_code/15290980528/
Traceback (most recent call last):
  File "/home/python/.virtualenvs/gangquan_12/lib/python3.5/site-packages/rest_framework/views.py", line 492, in dispatch
    response = handler(request, *args, **kwargs)
  File "/home/python/Desktop/gangquanwang/gangquan_12/gangquan_12/apps/verifications/views.py", line 47, in get
    serialzier.is_valid(raise_exception=True)
  File "/home/python/.virtualenvs/gangquan_12/lib/python3.5/site-packages/rest_framework/serializers.py", line 244, in is_valid
    raise ValidationError(self.errors)
rest_framework.exceptions.ValidationError: {'image_code_id': [ErrorDetail(string='该字段是必填项。', code='required')], 'text': [ErrorDetail(string='请确保这个字段不能超过 4 个字符。', code='max_length')]}

During handling of the above exception, another exception occurred:

Traceback (most recent call last):
  File "/home/python/.virtualenvs/gangquan_12/lib/python3.5/site-packages/rest_framework/settings.py", line 183, in import_from_string
    module = import_module(module_path)
  File "/home/python/.virtualenvs/gangquan_12/lib/python3.5/importlib/__init__.py", line 126, in import_module
    return _bootstrap._gcd_import(name[level:], package, level)
  File "<frozen importlib._bootstrap>", line 986, in _gcd_import
  File "<frozen importlib._bootstrap>", line 969, in _find_and_load
  File "<frozen importlib._bootstrap>", line 956, in _find_and_load_unlocked
ImportError: No module named 'gangquan_12.utils.exceptions'

During handling of the above exception, another exception occurred:

Traceback (most recent call last):
  File "/home/python/.virtualenvs/gangquan_12/lib/python3.5/site-packages/django/core/handlers/exception.py", line 41, in inner
    response = get_response(request)
  File "/home/python/.virtualenvs/gangquan_12/lib/python3.5/site-packages/django/core/handlers/base.py", line 187, in _get_response
    response = self.process_exception_by_middleware(e, request)
  File "/home/python/.virtualenvs/gangquan_12/lib/python3.5/site-packages/django/core/handlers/base.py", line 185, in _get_response
    response = wrapped_callback(request, *callback_args, **callback_kwargs)
  File "/home/python/.virtualenvs/gangquan_12/lib/python3.5/site-packages/django/views/decorators/csrf.py", line 58, in wrapped_view
    return view_func(*args, **kwargs)
  File "/home/python/.virtualenvs/gangquan_12/lib/python3.5/site-packages/django/views/generic/base.py", line 68, in view
    return self.dispatch(request, *args, **kwargs)
  File "/home/python/.virtualenvs/gangquan_12/lib/python3.5/site-packages/rest_framework/views.py", line 495, in dispatch
    response = self.handle_exception(exc)
  File "/home/python/.virtualenvs/gangquan_12/lib/python3.5/site-packages/rest_framework/views.py", line 449, in handle_exception
    exception_handler = self.get_exception_handler()
  File "/home/python/.virtualenvs/gangquan_12/lib/python3.5/site-packages/rest_framework/views.py", line 300, in get_exception_handler
    return self.settings.EXCEPTION_HANDLER
  File "/home/python/.virtualenvs/gangquan_12/lib/python3.5/site-packages/rest_framework/settings.py", line 227, in __getattr__
    val = perform_import(val, attr)
  File "/home/python/.virtualenvs/gangquan_12/lib/python3.5/site-packages/rest_framework/settings.py", line 170, in perform_import
    return import_from_string(val, setting_name)
  File "/home/python/.virtualenvs/gangquan_12/lib/python3.5/site-packages/rest_framework/settings.py", line 187, in import_from_string
    raise ImportError(msg)
ImportError: Could not import 'gangquan_12.utils.exceptions.exception_handler' for API setting 'EXCEPTION_HANDLER'. ImportError: No module named 'gangquan_12.utils.exceptions'.
ERROR 2019-07-01 18:21:41,181 basehttp 124 "GET /sms_code/15290980528/?text=12345&bbb=3333 HTTP/1.1" 500 128099
INFO 2019-07-01 18:24:29,829 basehttp 124 "GET /image_codes/aa10d41a-e1a4-4809-86ac-3acd1fc5cc99/ HTTP/1.1" 200 3101
INFO 2019-07-01 18:35:58,234 basehttp 124 "GET /image_codes/a15ccdde-f8ed-4a27-9290-67d47507877b/ HTTP/1.1" 200 3230
INFO 2019-07-01 18:36:17,088 basehttp 124 "GET /image_codes/8b6d4652-3057-4837-a20c-87da5f30cb41/ HTTP/1.1" 200 3625
WARNING 2019-07-01 18:36:32,929 base 152 Not Found: /sms_codes/15290980528/
WARNING 2019-07-01 18:36:32,930 basehttp 124 "GET /sms_codes/15290980528/?text=wwww&image_code_id=8b6d4652-3057-4837-a20c-87da5f30cb41 HTTP/1.1" 404 2452
WARNING 2019-07-01 18:36:53,493 base 152 Not Found: /sms_codes/15290980528/
WARNING 2019-07-01 18:36:53,494 basehttp 124 "GET /sms_codes/15290980528/?text=wwww&image_code_id=8b6d4652-3057-4837-a20c-87da5f30cb41 HTTP/1.1" 404 2452
WARNING 2019-07-01 18:36:53,599 base 152 Not Found: /favicon.ico
WARNING 2019-07-01 18:36:53,600 basehttp 124 "GET /favicon.ico HTTP/1.1" 404 2354
WARNING 2019-07-01 18:37:37,647 base 152 Not Found: /sms_codes/15290980528/
WARNING 2019-07-01 18:37:37,649 basehttp 124 "GET /sms_codes/15290980528/?text=wwww&image_code_id=8b6d4652-3057-4837-a20c-87da5f30cb41 HTTP/1.1" 404 2452
WARNING 2019-07-01 18:38:04,252 base 152 Not Found: /sms_codes/15290980528/
WARNING 2019-07-01 18:38:04,253 basehttp 124 "GET /sms_codes/15290980528/?text=wwww&image_code_id=8b6d4652-3057-4837-a20c-87da5f30cb41 HTTP/1.1" 404 2452
INFO 2019-07-01 18:38:45,656 basehttp 124 "GET /image_codes/a1f41168-e6c2-4aca-929f-a124ee3a39ff/ HTTP/1.1" 200 3500
WARNING 2019-07-01 18:38:56,588 base 152 Not Found: /sms_codes/15290980528/
WARNING 2019-07-01 18:38:56,589 basehttp 124 "GET /sms_codes/15290980528/?text=qwet&image_code_id=a1f41168-e6c2-4aca-929f-a124ee3a39ff HTTP/1.1" 404 2452
WARNING 2019-07-01 18:39:10,626 base 152 Not Found: /sms_codes/15290980528/
WARNING 2019-07-01 18:39:10,627 basehttp 124 "GET /sms_codes/15290980528/?text=qwet&image_code_id=a1f41168-e6c2-4aca-929f-a124ee3a39ff HTTP/1.1" 404 2452
WARNING 2019-07-01 18:39:50,407 base 152 Not Found: /sms_codes/15290980528/
WARNING 2019-07-01 18:39:50,408 basehttp 124 "GET /sms_codes/15290980528/?text=qwet&image_code_id=a1f41168-e6c2-4aca-929f-a124ee3a39ff HTTP/1.1" 404 2452
INFO 2019-07-01 18:40:13,209 basehttp 124 "GET /image_codes/a11e7b0f-1bb3-4639-af65-d8ce15ffcc8c/ HTTP/1.1" 200 2918
ERROR 2019-07-01 18:40:26,765 exception 135 Internal Server Error: /sms_codes/15290980528/
Traceback (most recent call last):
  File "/home/python/.virtualenvs/gangquan_12/lib/python3.5/site-packages/rest_framework/views.py", line 492, in dispatch
    response = handler(request, *args, **kwargs)
  File "/home/python/Desktop/gangquanwang/gangquan_12/gangquan_12/apps/verifications/views.py", line 47, in get
    serialzier.is_valid(raise_exception=True)
  File "/home/python/.virtualenvs/gangquan_12/lib/python3.5/site-packages/rest_framework/serializers.py", line 244, in is_valid
    raise ValidationError(self.errors)
rest_framework.exceptions.ValidationError: {'non_field_errors': [ErrorDetail(string='验证码输入不正确', code='invalid')]}

During handling of the above exception, another exception occurred:

Traceback (most recent call last):
  File "/home/python/.virtualenvs/gangquan_12/lib/python3.5/site-packages/rest_framework/settings.py", line 183, in import_from_string
    module = import_module(module_path)
  File "/home/python/.virtualenvs/gangquan_12/lib/python3.5/importlib/__init__.py", line 126, in import_module
    return _bootstrap._gcd_import(name[level:], package, level)
  File "<frozen importlib._bootstrap>", line 986, in _gcd_import
  File "<frozen importlib._bootstrap>", line 969, in _find_and_load
  File "<frozen importlib._bootstrap>", line 956, in _find_and_load_unlocked
ImportError: No module named 'gangquan_12.utils.exceptions'

During handling of the above exception, another exception occurred:

Traceback (most recent call last):
  File "/home/python/.virtualenvs/gangquan_12/lib/python3.5/site-packages/django/core/handlers/exception.py", line 41, in inner
    response = get_response(request)
  File "/home/python/.virtualenvs/gangquan_12/lib/python3.5/site-packages/django/core/handlers/base.py", line 187, in _get_response
    response = self.process_exception_by_middleware(e, request)
  File "/home/python/.virtualenvs/gangquan_12/lib/python3.5/site-packages/django/core/handlers/base.py", line 185, in _get_response
    response = wrapped_callback(request, *callback_args, **callback_kwargs)
  File "/home/python/.virtualenvs/gangquan_12/lib/python3.5/site-packages/django/views/decorators/csrf.py", line 58, in wrapped_view
    return view_func(*args, **kwargs)
  File "/home/python/.virtualenvs/gangquan_12/lib/python3.5/site-packages/django/views/generic/base.py", line 68, in view
    return self.dispatch(request, *args, **kwargs)
  File "/home/python/.virtualenvs/gangquan_12/lib/python3.5/site-packages/rest_framework/views.py", line 495, in dispatch
    response = self.handle_exception(exc)
  File "/home/python/.virtualenvs/gangquan_12/lib/python3.5/site-packages/rest_framework/views.py", line 449, in handle_exception
    exception_handler = self.get_exception_handler()
  File "/home/python/.virtualenvs/gangquan_12/lib/python3.5/site-packages/rest_framework/views.py", line 300, in get_exception_handler
    return self.settings.EXCEPTION_HANDLER
  File "/home/python/.virtualenvs/gangquan_12/lib/python3.5/site-packages/rest_framework/settings.py", line 227, in __getattr__
    val = perform_import(val, attr)
  File "/home/python/.virtualenvs/gangquan_12/lib/python3.5/site-packages/rest_framework/settings.py", line 170, in perform_import
    return import_from_string(val, setting_name)
  File "/home/python/.virtualenvs/gangquan_12/lib/python3.5/site-packages/rest_framework/settings.py", line 187, in import_from_string
    raise ImportError(msg)
ImportError: Could not import 'gangquan_12.utils.exceptions.exception_handler' for API setting 'EXCEPTION_HANDLER'. ImportError: No module named 'gangquan_12.utils.exceptions'.
ERROR 2019-07-01 18:40:26,849 basehttp 124 "GET /sms_codes/15290980528/?text=pud8&image_code_id=a11e7b0f-1bb3-4639-af65-d8ce15ffcc8c HTTP/1.1" 500 126629
INFO 2019-07-01 18:41:27,914 basehttp 124 "GET /image_codes/5539cb69-90de-4435-8a5b-d80b495e9f79/ HTTP/1.1" 200 3091
INFO 2019-07-01 18:41:34,861 basehttp 124 "GET /image_codes/ee86307d-93f0-420b-8568-717eb9150fa5/ HTTP/1.1" 200 2994
WARNING 2019-07-01 18:42:00,830 views 77 发送短信验证码(失败) mobile:15290980528
ERROR 2019-07-01 18:42:00,831 basehttp 124 "GET /sms_codes/15290980528/?text=zxla&image_code_id=ee86307d-93f0-420b-8568-717eb9150fa5 HTTP/1.1" 507 32
INFO 2019-07-01 18:42:55,948 basehttp 124 "GET /image_codes/ea53ff01-e727-4902-abca-0abd2f8c6455/ HTTP/1.1" 200 3103
WARNING 2019-07-01 18:43:32,495 base 152 Not Found: /
WARNING 2019-07-01 18:43:32,496 basehttp 124 "GET / HTTP/1.1" 404 2298
WARNING 2019-07-01 18:43:32,575 base 152 Not Found: /favicon.ico
WARNING 2019-07-01 18:43:32,575 basehttp 124 "GET /favicon.ico HTTP/1.1" 404 2349
WARNING 2019-07-01 18:44:21,853 base 152 Not Found: /sms_codes/15290980528/text=XB97&image_code_id=ea53ff01-e727-4902-abca-0abd2f8c6455
WARNING 2019-07-01 18:44:21,854 basehttp 124 "GET /sms_codes/15290980528/text=XB97&image_code_id=ea53ff01-e727-4902-abca-0abd2f8c6455 HTTP/1.1" 404 2578
WARNING 2019-07-01 18:45:48,603 views 77 发送短信验证码(失败) mobile:15290980528
ERROR 2019-07-01 18:45:48,915 basehttp 124 "GET /sms_codes/15290980528/?text=XB97&image_code_id=ea53ff01-e727-4902-abca-0abd2f8c6455 HTTP/1.1" 507 5711
INFO 2019-07-01 18:45:48,955 basehttp 124 "GET /static/rest_framework/css/bootstrap-tweaks.css HTTP/1.1" 200 3385
INFO 2019-07-01 18:45:48,958 basehttp 124 "GET /static/rest_framework/css/default.css HTTP/1.1" 200 1131
INFO 2019-07-01 18:45:48,960 basehttp 124 "GET /static/rest_framework/css/prettify.css HTTP/1.1" 200 817
INFO 2019-07-01 18:45:48,967 basehttp 124 "GET /static/rest_framework/js/bootstrap.min.js HTTP/1.1" 200 37608
INFO 2019-07-01 18:45:48,970 basehttp 124 "GET /static/rest_framework/js/ajax-form.js HTTP/1.1" 200 3597
INFO 2019-07-01 18:45:48,973 basehttp 124 "GET /static/rest_framework/js/prettify-min.js HTTP/1.1" 200 13632
INFO 2019-07-01 18:45:48,974 basehttp 124 "GET /static/rest_framework/js/jquery-3.3.1.min.js HTTP/1.1" 200 86927
INFO 2019-07-01 18:45:48,979 basehttp 124 "GET /static/rest_framework/js/csrf.js HTTP/1.1" 200 1719
INFO 2019-07-01 18:45:48,998 basehttp 124 "GET /static/rest_framework/js/default.js HTTP/1.1" 200 1268
INFO 2019-07-01 18:45:49,000 basehttp 124 "GET /static/rest_framework/css/bootstrap.min.css HTTP/1.1" 200 121457
INFO 2019-07-01 18:45:49,250 basehttp 124 "GET /static/rest_framework/img/grid.png HTTP/1.1" 200 1458
INFO 2019-07-01 18:55:17,743 basehttp 124 "GET /image_codes/f41ea84a-0f94-46c4-a5fe-17f822c13659/ HTTP/1.1" 200 3194
WARNING 2019-07-01 18:57:05,102 views 77 发送短信验证码(失败) mobile:15290980528
ERROR 2019-07-01 18:57:05,126 basehttp 124 "GET /sms_codes/15290980528/?text=PW9L&image_code_id=f41ea84a-0f94-46c4-a5fe-17f822c13659 HTTP/1.1" 507 5711
INFO 2019-07-01 19:02:08,796 basehttp 124 "GET /image_codes/475596d3-9fcd-4e69-80dd-566e79c034fe/ HTTP/1.1" 200 3605
INFO 2019-07-01 19:02:59,435 views 74 发送短信验证码(正常) mobile:15290980528
INFO 2019-07-01 19:02:59,459 basehttp 124 "GET /sms_codes/15290980528/?text=8JPM&image_code_id=475596d3-9fcd-4e69-80dd-566e79c034fe HTTP/1.1" 200 5693
ERROR 2019-07-01 19:10:08,324 exception 135 Internal Server Error: /sms_codes/15290980528/
Traceback (most recent call last):
  File "/home/python/.virtualenvs/gangquan_12/lib/python3.5/site-packages/rest_framework/views.py", line 492, in dispatch
    response = handler(request, *args, **kwargs)
  File "/home/python/Desktop/gangquanwang/gangquan_12/gangquan_12/apps/verifications/views.py", line 47, in get
    serialzier.is_valid(raise_exception=True)
  File "/home/python/.virtualenvs/gangquan_12/lib/python3.5/site-packages/rest_framework/serializers.py", line 244, in is_valid
    raise ValidationError(self.errors)
rest_framework.exceptions.ValidationError: {'non_field_errors': [ErrorDetail(string='图片验证码无效', code='invalid')]}

During handling of the above exception, another exception occurred:

Traceback (most recent call last):
  File "/home/python/.virtualenvs/gangquan_12/lib/python3.5/site-packages/rest_framework/settings.py", line 183, in import_from_string
    module = import_module(module_path)
  File "/home/python/.virtualenvs/gangquan_12/lib/python3.5/importlib/__init__.py", line 126, in import_module
    return _bootstrap._gcd_import(name[level:], package, level)
  File "<frozen importlib._bootstrap>", line 986, in _gcd_import
  File "<frozen importlib._bootstrap>", line 969, in _find_and_load
  File "<frozen importlib._bootstrap>", line 956, in _find_and_load_unlocked
ImportError: No module named 'gangquan_12.utils.exceptions'

During handling of the above exception, another exception occurred:

Traceback (most recent call last):
  File "/home/python/.virtualenvs/gangquan_12/lib/python3.5/site-packages/django/core/handlers/exception.py", line 41, in inner
    response = get_response(request)
  File "/home/python/.virtualenvs/gangquan_12/lib/python3.5/site-packages/django/core/handlers/base.py", line 187, in _get_response
    response = self.process_exception_by_middleware(e, request)
  File "/home/python/.virtualenvs/gangquan_12/lib/python3.5/site-packages/django/core/handlers/base.py", line 185, in _get_response
    response = wrapped_callback(request, *callback_args, **callback_kwargs)
  File "/home/python/.virtualenvs/gangquan_12/lib/python3.5/site-packages/django/views/decorators/csrf.py", line 58, in wrapped_view
    return view_func(*args, **kwargs)
  File "/home/python/.virtualenvs/gangquan_12/lib/python3.5/site-packages/django/views/generic/base.py", line 68, in view
    return self.dispatch(request, *args, **kwargs)
  File "/home/python/.virtualenvs/gangquan_12/lib/python3.5/site-packages/rest_framework/views.py", line 495, in dispatch
    response = self.handle_exception(exc)
  File "/home/python/.virtualenvs/gangquan_12/lib/python3.5/site-packages/rest_framework/views.py", line 449, in handle_exception
    exception_handler = self.get_exception_handler()
  File "/home/python/.virtualenvs/gangquan_12/lib/python3.5/site-packages/rest_framework/views.py", line 300, in get_exception_handler
    return self.settings.EXCEPTION_HANDLER
  File "/home/python/.virtualenvs/gangquan_12/lib/python3.5/site-packages/rest_framework/settings.py", line 227, in __getattr__
    val = perform_import(val, attr)
  File "/home/python/.virtualenvs/gangquan_12/lib/python3.5/site-packages/rest_framework/settings.py", line 170, in perform_import
    return import_from_string(val, setting_name)
  File "/home/python/.virtualenvs/gangquan_12/lib/python3.5/site-packages/rest_framework/settings.py", line 187, in import_from_string
    raise ImportError(msg)
ImportError: Could not import 'gangquan_12.utils.exceptions.exception_handler' for API setting 'EXCEPTION_HANDLER'. ImportError: No module named 'gangquan_12.utils.exceptions'.
ERROR 2019-07-01 19:10:08,591 basehttp 124 "GET /sms_codes/15290980528/?text=8jpm&image_code_id=475596d3-9fcd-4e69-80dd-566e79c034fe HTTP/1.1" 500 126620
INFO 2019-07-01 19:16:16,937 basehttp 124 "GET /image_codes/45e9fad2-7ca0-4363-875e-0f39804b8dc4/ HTTP/1.1" 200 3326
ERROR 2019-07-01 19:16:27,368 exception 135 Internal Server Error: /sms_codes/15290980528/
Traceback (most recent call last):
  File "/home/python/.virtualenvs/gangquan_12/lib/python3.5/site-packages/rest_framework/views.py", line 492, in dispatch
    response = handler(request, *args, **kwargs)
  File "/home/python/Desktop/gangquanwang/gangquan_12/gangquan_12/apps/verifications/views.py", line 47, in get
    serialzier.is_valid(raise_exception=True)
  File "/home/python/.virtualenvs/gangquan_12/lib/python3.5/site-packages/rest_framework/serializers.py", line 244, in is_valid
    raise ValidationError(self.errors)
rest_framework.exceptions.ValidationError: {'non_field_errors': [ErrorDetail(string='验证码输入不正确', code='invalid')]}

During handling of the above exception, another exception occurred:

Traceback (most recent call last):
  File "/home/python/.virtualenvs/gangquan_12/lib/python3.5/site-packages/rest_framework/settings.py", line 183, in import_from_string
    module = import_module(module_path)
  File "/home/python/.virtualenvs/gangquan_12/lib/python3.5/importlib/__init__.py", line 126, in import_module
    return _bootstrap._gcd_import(name[level:], package, level)
  File "<frozen importlib._bootstrap>", line 986, in _gcd_import
  File "<frozen importlib._bootstrap>", line 969, in _find_and_load
  File "<frozen importlib._bootstrap>", line 956, in _find_and_load_unlocked
ImportError: No module named 'gangquan_12.utils.exceptions'

During handling of the above exception, another exception occurred:

Traceback (most recent call last):
  File "/home/python/.virtualenvs/gangquan_12/lib/python3.5/site-packages/django/core/handlers/exception.py", line 41, in inner
    response = get_response(request)
  File "/home/python/.virtualenvs/gangquan_12/lib/python3.5/site-packages/django/core/handlers/base.py", line 187, in _get_response
    response = self.process_exception_by_middleware(e, request)
  File "/home/python/.virtualenvs/gangquan_12/lib/python3.5/site-packages/django/core/handlers/base.py", line 185, in _get_response
    response = wrapped_callback(request, *callback_args, **callback_kwargs)
  File "/home/python/.virtualenvs/gangquan_12/lib/python3.5/site-packages/django/views/decorators/csrf.py", line 58, in wrapped_view
    return view_func(*args, **kwargs)
  File "/home/python/.virtualenvs/gangquan_12/lib/python3.5/site-packages/django/views/generic/base.py", line 68, in view
    return self.dispatch(request, *args, **kwargs)
  File "/home/python/.virtualenvs/gangquan_12/lib/python3.5/site-packages/rest_framework/views.py", line 495, in dispatch
    response = self.handle_exception(exc)
  File "/home/python/.virtualenvs/gangquan_12/lib/python3.5/site-packages/rest_framework/views.py", line 449, in handle_exception
    exception_handler = self.get_exception_handler()
  File "/home/python/.virtualenvs/gangquan_12/lib/python3.5/site-packages/rest_framework/views.py", line 300, in get_exception_handler
    return self.settings.EXCEPTION_HANDLER
  File "/home/python/.virtualenvs/gangquan_12/lib/python3.5/site-packages/rest_framework/settings.py", line 227, in __getattr__
    val = perform_import(val, attr)
  File "/home/python/.virtualenvs/gangquan_12/lib/python3.5/site-packages/rest_framework/settings.py", line 170, in perform_import
    return import_from_string(val, setting_name)
  File "/home/python/.virtualenvs/gangquan_12/lib/python3.5/site-packages/rest_framework/settings.py", line 187, in import_from_string
    raise ImportError(msg)
ImportError: Could not import 'gangquan_12.utils.exceptions.exception_handler' for API setting 'EXCEPTION_HANDLER'. ImportError: No module named 'gangquan_12.utils.exceptions'.
ERROR 2019-07-01 19:16:27,448 basehttp 124 "GET /sms_codes/15290980528/?text=1234&image_code_id=45e9fad2-7ca0-4363-875e-0f39804b8dc4 HTTP/1.1" 500 126629
INFO 2019-07-01 19:16:59,798 basehttp 124 "GET /image_codes/e7278cc0-40be-41f0-8020-0ec959674518/ HTTP/1.1" 200 2968
INFO 2019-07-01 19:17:35,313 basehttp 124 "GET /image_codes/f2b231c5-22f8-4ed6-a273-2e531df013dd/ HTTP/1.1" 200 2924
INFO 2019-07-01 19:17:50,326 views 74 发送短信验证码(正常) mobile:15290980528
INFO 2019-07-01 19:17:50,326 basehttp 124 "GET /sms_codes/15290980528/?text=m5r3&image_code_id=f2b231c5-22f8-4ed6-a273-2e531df013dd HTTP/1.1" 200 32
INFO 2019-07-01 19:18:30,661 basehttp 124 "GET /image_codes/83f3b58c-dc44-4713-99b5-acce60e4b904/ HTTP/1.1" 200 3150
ERROR 2019-07-01 19:18:41,511 exception 135 Internal Server Error: /sms_codes/15290980528/
Traceback (most recent call last):
  File "/home/python/.virtualenvs/gangquan_12/lib/python3.5/site-packages/rest_framework/views.py", line 492, in dispatch
    response = handler(request, *args, **kwargs)
  File "/home/python/Desktop/gangquanwang/gangquan_12/gangquan_12/apps/verifications/views.py", line 47, in get
    serialzier.is_valid(raise_exception=True)
  File "/home/python/.virtualenvs/gangquan_12/lib/python3.5/site-packages/rest_framework/serializers.py", line 244, in is_valid
    raise ValidationError(self.errors)
rest_framework.exceptions.ValidationError: {'non_field_errors': [ErrorDetail(string='请求过于频繁', code='invalid')]}

During handling of the above exception, another exception occurred:

Traceback (most recent call last):
  File "/home/python/.virtualenvs/gangquan_12/lib/python3.5/site-packages/rest_framework/settings.py", line 183, in import_from_string
    module = import_module(module_path)
  File "/home/python/.virtualenvs/gangquan_12/lib/python3.5/importlib/__init__.py", line 126, in import_module
    return _bootstrap._gcd_import(name[level:], package, level)
  File "<frozen importlib._bootstrap>", line 986, in _gcd_import
  File "<frozen importlib._bootstrap>", line 969, in _find_and_load
  File "<frozen importlib._bootstrap>", line 956, in _find_and_load_unlocked
ImportError: No module named 'gangquan_12.utils.exceptions'

During handling of the above exception, another exception occurred:

Traceback (most recent call last):
  File "/home/python/.virtualenvs/gangquan_12/lib/python3.5/site-packages/django/core/handlers/exception.py", line 41, in inner
    response = get_response(request)
  File "/home/python/.virtualenvs/gangquan_12/lib/python3.5/site-packages/django/core/handlers/base.py", line 187, in _get_response
    response = self.process_exception_by_middleware(e, request)
  File "/home/python/.virtualenvs/gangquan_12/lib/python3.5/site-packages/django/core/handlers/base.py", line 185, in _get_response
    response = wrapped_callback(request, *callback_args, **callback_kwargs)
  File "/home/python/.virtualenvs/gangquan_12/lib/python3.5/site-packages/django/views/decorators/csrf.py", line 58, in wrapped_view
    return view_func(*args, **kwargs)
  File "/home/python/.virtualenvs/gangquan_12/lib/python3.5/site-packages/django/views/generic/base.py", line 68, in view
    return self.dispatch(request, *args, **kwargs)
  File "/home/python/.virtualenvs/gangquan_12/lib/python3.5/site-packages/rest_framework/views.py", line 495, in dispatch
    response = self.handle_exception(exc)
  File "/home/python/.virtualenvs/gangquan_12/lib/python3.5/site-packages/rest_framework/views.py", line 449, in handle_exception
    exception_handler = self.get_exception_handler()
  File "/home/python/.virtualenvs/gangquan_12/lib/python3.5/site-packages/rest_framework/views.py", line 300, in get_exception_handler
    return self.settings.EXCEPTION_HANDLER
  File "/home/python/.virtualenvs/gangquan_12/lib/python3.5/site-packages/rest_framework/settings.py", line 227, in __getattr__
    val = perform_import(val, attr)
  File "/home/python/.virtualenvs/gangquan_12/lib/python3.5/site-packages/rest_framework/settings.py", line 170, in perform_import
    return import_from_string(val, setting_name)
  File "/home/python/.virtualenvs/gangquan_12/lib/python3.5/site-packages/rest_framework/settings.py", line 187, in import_from_string
    raise ImportError(msg)
ImportError: Could not import 'gangquan_12.utils.exceptions.exception_handler' for API setting 'EXCEPTION_HANDLER'. ImportError: No module named 'gangquan_12.utils.exceptions'.
ERROR 2019-07-01 19:18:41,588 basehttp 124 "GET /sms_codes/15290980528/?text=flgy&image_code_id=83f3b58c-dc44-4713-99b5-acce60e4b904 HTTP/1.1" 500 126611
INFO 2019-07-01 19:19:35,752 basehttp 124 "GET /image_codes/b6d5f129-ccd1-43c5-aeab-e76985c084fa/ HTTP/1.1" 200 2983
INFO 2019-07-01 19:20:23,606 views 74 发送短信验证码(正常) mobile:15290980528
INFO 2019-07-01 19:20:26,979 basehttp 124 "GET /sms_codes/15290980528/?text=hffc&image_code_id=b6d5f129-ccd1-43c5-aeab-e76985c084fa HTTP/1.1" 200 32
INFO 2019-07-01 19:22:37,644 basehttp 124 "GET /image_codes/d18cb6d1-57e2-406b-aacd-f4ec1cb5f426/ HTTP/1.1" 200 3150
INFO 2019-07-01 19:23:46,526 basehttp 124 "GET /image_codes/a11d8783-ebb7-4705-aa4c-e8940eac1e41/ HTTP/1.1" 200 3246
INFO 2019-07-01 19:24:35,886 views 74 发送短信验证码(正常) mobile:15290980528
INFO 2019-07-01 19:24:35,888 basehttp 124 "GET /sms_codes/15290980528/?text=cfze&image_code_id=a11d8783-ebb7-4705-aa4c-e8940eac1e41 HTTP/1.1" 200 32
INFO 2019-07-01 19:27:43,270 basehttp 124 "GET /image_codes/00e378f6-36c0-4f6f-9d52-e889fdeaf628/ HTTP/1.1" 200 2907
INFO 2019-07-01 19:28:14,900 views 76 发送短信验证码(正常) mobile:15290980528
INFO 2019-07-01 19:28:17,763 basehttp 124 "GET /sms_codes/15290980528/?text=pvc6&image_code_id=00e378f6-36c0-4f6f-9d52-e889fdeaf628 HTTP/1.1" 200 32
INFO 2019-07-01 19:31:04,846 basehttp 124 "GET /image_codes/117430bc-1641-49e5-9d9d-e9530e2015f8/ HTTP/1.1" 200 3662
INFO 2019-07-01 19:31:39,079 views 76 发送短信验证码(正常) mobile:15290980528
INFO 2019-07-01 19:31:41,274 basehttp 124 "GET /sms_codes/15290980528/?text=yuhf&image_code_id=117430bc-1641-49e5-9d9d-e9530e2015f8 HTTP/1.1" 200 32
INFO 2019-07-01 19:35:05,640 basehttp 124 "GET /image_codes/9f6777f5-5b6d-4988-a38c-71ade48e4459/ HTTP/1.1" 200 2815
INFO 2019-07-01 19:35:19,614 basehttp 124 "GET /image_codes/2ec50e83-3b34-4614-b152-9cffed9d707d/ HTTP/1.1" 200 3199
INFO 2019-07-01 19:35:28,359 views 76 发送短信验证码(正常) mobile:15290980528
INFO 2019-07-01 19:35:28,360 basehttp 124 "GET /sms_codes/15290980528/?text=y6ke&image_code_id=2ec50e83-3b34-4614-b152-9cffed9d707d HTTP/1.1" 200 32
INFO 2019-07-04 11:04:27,302 basehttp 124 "GET /image_codes/65f3d6bd-c552-4bfd-9ec3-dcfb9d0fe230/ HTTP/1.1" 200 3151
INFO 2019-07-04 11:05:59,289 basehttp 124 "GET /image_codes/b539d854-7784-4b8c-a70f-9b251071d206/ HTTP/1.1" 200 3659
INFO 2019-07-04 11:06:12,327 basehttp 124 "GET /sms_codes/18522222222/?text=GRHE&image_code_id=b539d854-7784-4b8c-a70f-9b251071d206 HTTP/1.1" 200 16
INFO 2019-07-04 11:13:47,260 basehttp 124 "GET /image_codes/0a88a4b1-3717-4a69-ab31-84bab0147abb/ HTTP/1.1" 200 3491
INFO 2019-07-04 11:14:11,934 basehttp 124 "GET /sms_codes/18539022886/?text=7WCL&image_code_id=0a88a4b1-3717-4a69-ab31-84bab0147abb HTTP/1.1" 200 16
INFO 2019-07-04 11:15:56,532 basehttp 124 "GET /image_codes/fcf8c89e-e430-4a95-b3e3-ca85283e74d4/ HTTP/1.1" 200 3052
INFO 2019-07-04 11:16:13,574 basehttp 124 "GET /sms_codes/18539022886/?text=Y8AU&image_code_id=fcf8c89e-e430-4a95-b3e3-ca85283e74d4 HTTP/1.1" 200 16
ERROR 2019-07-04 11:18:52,757 exception 135 Internal Server Error: /sms_codes/18539022886/
Traceback (most recent call last):
  File "/home/python/.virtualenvs/gangquan_12/lib/python3.5/site-packages/rest_framework/views.py", line 492, in dispatch
    response = handler(request, *args, **kwargs)
  File "/home/python/Desktop/gangquanwang/gangquan_12/gangquan_12/apps/verifications/views.py", line 49, in get
    serialzier.is_valid(raise_exception=True)
  File "/home/python/.virtualenvs/gangquan_12/lib/python3.5/site-packages/rest_framework/serializers.py", line 244, in is_valid
    raise ValidationError(self.errors)
rest_framework.exceptions.ValidationError: {'non_field_errors': [ErrorDetail(string='图片验证码无效', code='invalid')]}

During handling of the above exception, another exception occurred:

Traceback (most recent call last):
  File "/home/python/.virtualenvs/gangquan_12/lib/python3.5/site-packages/rest_framework/settings.py", line 183, in import_from_string
    module = import_module(module_path)
  File "/home/python/.virtualenvs/gangquan_12/lib/python3.5/importlib/__init__.py", line 126, in import_module
    return _bootstrap._gcd_import(name[level:], package, level)
  File "<frozen importlib._bootstrap>", line 986, in _gcd_import
  File "<frozen importlib._bootstrap>", line 969, in _find_and_load
  File "<frozen importlib._bootstrap>", line 956, in _find_and_load_unlocked
ImportError: No module named 'gangquan_12.utils.exceptions'

During handling of the above exception, another exception occurred:

Traceback (most recent call last):
  File "/home/python/.virtualenvs/gangquan_12/lib/python3.5/site-packages/django/core/handlers/exception.py", line 41, in inner
    response = get_response(request)
  File "/home/python/.virtualenvs/gangquan_12/lib/python3.5/site-packages/django/core/handlers/base.py", line 187, in _get_response
    response = self.process_exception_by_middleware(e, request)
  File "/home/python/.virtualenvs/gangquan_12/lib/python3.5/site-packages/django/core/handlers/base.py", line 185, in _get_response
    response = wrapped_callback(request, *callback_args, **callback_kwargs)
  File "/home/python/.virtualenvs/gangquan_12/lib/python3.5/site-packages/django/views/decorators/csrf.py", line 58, in wrapped_view
    return view_func(*args, **kwargs)
  File "/home/python/.virtualenvs/gangquan_12/lib/python3.5/site-packages/django/views/generic/base.py", line 68, in view
    return self.dispatch(request, *args, **kwargs)
  File "/home/python/.virtualenvs/gangquan_12/lib/python3.5/site-packages/rest_framework/views.py", line 495, in dispatch
    response = self.handle_exception(exc)
  File "/home/python/.virtualenvs/gangquan_12/lib/python3.5/site-packages/rest_framework/views.py", line 449, in handle_exception
    exception_handler = self.get_exception_handler()
  File "/home/python/.virtualenvs/gangquan_12/lib/python3.5/site-packages/rest_framework/views.py", line 300, in get_exception_handler
    return self.settings.EXCEPTION_HANDLER
  File "/home/python/.virtualenvs/gangquan_12/lib/python3.5/site-packages/rest_framework/settings.py", line 227, in __getattr__
    val = perform_import(val, attr)
  File "/home/python/.virtualenvs/gangquan_12/lib/python3.5/site-packages/rest_framework/settings.py", line 170, in perform_import
    return import_from_string(val, setting_name)
  File "/home/python/.virtualenvs/gangquan_12/lib/python3.5/site-packages/rest_framework/settings.py", line 187, in import_from_string
    raise ImportError(msg)
ImportError: Could not import 'gangquan_12.utils.exceptions.exception_handler' for API setting 'EXCEPTION_HANDLER'. ImportError: No module named 'gangquan_12.utils.exceptions'.
ERROR 2019-07-04 11:18:53,003 basehttp 124 "GET /sms_codes/18539022886/?text=Y8AU&image_code_id=fcf8c89e-e430-4a95-b3e3-ca85283e74d4 HTTP/1.1" 500 127160
ERROR 2019-07-04 11:18:57,342 exception 135 Internal Server Error: /sms_codes/18539022886/
Traceback (most recent call last):
  File "/home/python/.virtualenvs/gangquan_12/lib/python3.5/site-packages/rest_framework/views.py", line 492, in dispatch
    response = handler(request, *args, **kwargs)
  File "/home/python/Desktop/gangquanwang/gangquan_12/gangquan_12/apps/verifications/views.py", line 49, in get
    serialzier.is_valid(raise_exception=True)
  File "/home/python/.virtualenvs/gangquan_12/lib/python3.5/site-packages/rest_framework/serializers.py", line 244, in is_valid
    raise ValidationError(self.errors)
rest_framework.exceptions.ValidationError: {'non_field_errors': [ErrorDetail(string='图片验证码无效', code='invalid')]}

During handling of the above exception, another exception occurred:

Traceback (most recent call last):
  File "/home/python/.virtualenvs/gangquan_12/lib/python3.5/site-packages/rest_framework/settings.py", line 183, in import_from_string
    module = import_module(module_path)
  File "/home/python/.virtualenvs/gangquan_12/lib/python3.5/importlib/__init__.py", line 126, in import_module
    return _bootstrap._gcd_import(name[level:], package, level)
  File "<frozen importlib._bootstrap>", line 986, in _gcd_import
  File "<frozen importlib._bootstrap>", line 969, in _find_and_load
  File "<frozen importlib._bootstrap>", line 956, in _find_and_load_unlocked
ImportError: No module named 'gangquan_12.utils.exceptions'

During handling of the above exception, another exception occurred:

Traceback (most recent call last):
  File "/home/python/.virtualenvs/gangquan_12/lib/python3.5/site-packages/django/core/handlers/exception.py", line 41, in inner
    response = get_response(request)
  File "/home/python/.virtualenvs/gangquan_12/lib/python3.5/site-packages/django/core/handlers/base.py", line 187, in _get_response
    response = self.process_exception_by_middleware(e, request)
  File "/home/python/.virtualenvs/gangquan_12/lib/python3.5/site-packages/django/core/handlers/base.py", line 185, in _get_response
    response = wrapped_callback(request, *callback_args, **callback_kwargs)
  File "/home/python/.virtualenvs/gangquan_12/lib/python3.5/site-packages/django/views/decorators/csrf.py", line 58, in wrapped_view
    return view_func(*args, **kwargs)
  File "/home/python/.virtualenvs/gangquan_12/lib/python3.5/site-packages/django/views/generic/base.py", line 68, in view
    return self.dispatch(request, *args, **kwargs)
  File "/home/python/.virtualenvs/gangquan_12/lib/python3.5/site-packages/rest_framework/views.py", line 495, in dispatch
    response = self.handle_exception(exc)
  File "/home/python/.virtualenvs/gangquan_12/lib/python3.5/site-packages/rest_framework/views.py", line 449, in handle_exception
    exception_handler = self.get_exception_handler()
  File "/home/python/.virtualenvs/gangquan_12/lib/python3.5/site-packages/rest_framework/views.py", line 300, in get_exception_handler
    return self.settings.EXCEPTION_HANDLER
  File "/home/python/.virtualenvs/gangquan_12/lib/python3.5/site-packages/rest_framework/settings.py", line 227, in __getattr__
    val = perform_import(val, attr)
  File "/home/python/.virtualenvs/gangquan_12/lib/python3.5/site-packages/rest_framework/settings.py", line 170, in perform_import
    return import_from_string(val, setting_name)
  File "/home/python/.virtualenvs/gangquan_12/lib/python3.5/site-packages/rest_framework/settings.py", line 187, in import_from_string
    raise ImportError(msg)
ImportError: Could not import 'gangquan_12.utils.exceptions.exception_handler' for API setting 'EXCEPTION_HANDLER'. ImportError: No module named 'gangquan_12.utils.exceptions'.
ERROR 2019-07-04 11:18:57,428 basehttp 124 "GET /sms_codes/18539022886/?text=Y8AU&image_code_id=fcf8c89e-e430-4a95-b3e3-ca85283e74d4 HTTP/1.1" 500 127160
